Workbook

Sheet MENU
B1: SISTEM PENGGEMUKAN SAPI POTONG — TERINTEGRASI
B3: PENGATURAN USAHA
B4: PT/UD Contoh Ternak | C4: <-- Nama Usaha
B5: 500000000 | C5: <-- Modal Disetor (Rp) | dipakai di Neraca & Arus Kas
B6: Tahun 2025/2026 | C6: <-- Periode Laporan
B8: DAFTAR SHEET & FUNGSINYA
B9: Nama Sheet | C9: Fungsi | D9: Tipe
B10: M_Pakan | C10: Master jenis pakan & satuan | D10: INPUT
B11: M_AsetTetap | C11: Master aset tetap + penyusutan otomatis | D11: INPUT
B12: M_Batch | C12: Master batch/periode penggemukan (pengunci biaya + kandang) | D12: INPUT
B13: M_Sapi | C13: Master & pembelian sapi (isi Batch) | D13: INPUT
B14: Pakan_Masuk | C14: Pembelian/stok pakan masuk | D14: INPUT
B15: Pakan_Keluar | C15: Konsumsi pakan harian (per batch) | D15: INPUT
B16: Timbang | C16: Penimbangan bobot berkala | D16: INPUT
B17: Operasional | C17: Biaya operasional (tandai Batch) | D17: INPUT
B18: Penjualan | C18: Penjualan sapi | D18: INPUT
B19: Stok_Pakan | C19: Kartu stok pakan (valuasi rata-rata) | D19: OUTPUT
B20: HPP_Sapi | C20: HPP per ekor berbasis batch (mesin hitung) | D20: OUTPUT
... B23: DASHBOARD | C23: Ringkasan KPI & visual usaha | D23: OUTPUT
B25: PETUNJUK & KETERANGAN
B26: Isi HANYA sel berwarna HIJAU (INPUT). Sel ABU-ABU dihitung otomatis (jangan diubah).
B27: Sheet OUTPUT terkunci (proteksi). Untuk membuka: menu Review > Unprotect Sheet (tanpa password).
B28: ALUR: buat Batch di M_Batch dulu -> tandai setiap sapi, pakan keluar, & operasional dengan Batch tsb.
B29: Metode: HPP akurat berbasis BATCH. Biaya pakan/operasional/penyusutan dikelompokkan per batch.
B30: Saat batch SELESAI: isi Tgl Selesai di M_Batch -> biaya & HPP batch itu TERKUNCI (margin historis tidak berubah).
B31: Alokasi operasional & penyusutan dalam batch: berdasarkan HARI pemeliharaan. Valuasi pakan: rata-rata tertimbang.
B32: Penyusutan batch = (penyusutan/bln semua aset) x lama batch (bulan). Kandang dicatat di M_Batch.
B33: Gunakan dropdown pada kolom Batch, Kode Pakan, ID Sapi, Jenis Biaya untuk hindari salah ketik.
B34: Kapasitas: 50 batch (3-4x/tahun x 10+ tahun). Cukup ketik di baris kosong berikutnya, formula sudah tersedia.

Sheet M_Pakan
A1: Kode Pakan | B1: Nama Pakan | C1: Jenis | D1: Satuan
A2: PK01 | B2: Rumput Gajah | C2: Rumput | D2: kg
A3: PK02 | B3: Konsentrat Sapi | C3: Konsentrat | D3: kg
A4: PK03 | B4: Mineral / Premix | C4: Mineral | D4: kg

Sheet M_AsetTetap
A1: Nama Aset | B1: Tgl Beli | C1: Harga Perolehan | D1: Umur Ekonomis (bln) | E1: Nilai Residu | F1: Penyusutan/Bln | G1: Umur Terpakai (bln) | H1: Akm. Penyusutan | I1: Nilai Buku
A2: Kandang Utama | B2: 45301 | C2: 150000000 | D2: 120 | E2: 15000000 | F2: =IF($A2="","",IFERROR(($C2-$E2)/$D2,0)) | G2: =IF($A2="","",IFERROR(DATEDIF($B2,TODAY(),"m"),0)) | H2: =IF($A2="","",MIN($C2-$E2,$F2*$G2)) | I2: =IF($A2="","",$C2-$H2)
A3: Mesin Chopper | B3: 45306 | C3: 18000000 | D3: 60 | E3: 1000000 | F3: =IF($A3="","",IFERROR(($C3-$E3)/$D3,0)) | G3: =IF($A3="","",IFERROR(DATEDIF($B3,TODAY(),"m"),0)) | H3: =IF($A3="","",MIN($C3-$E3,$F3*$G3)) | I3: =IF($A3="","",$C3-$H3)
A4: Timbangan Sapi | B4: 45323 | C4: 12000000 | D4: 60 | E4: 500000 | F4: =IF($A4="","",IFERROR(($C4-$E4)/$D4,0)) | G4: =IF($A4="","",IFERROR(DATEDIF($B4,TODAY(),"m"),0)) | H4: =IF($A4="","",MIN($C4-$E4,$F4*$G4)) | I4: =IF($A4="","",$C4-$H4)
A5: Karpet Karet Kandang | B5: 45323 | C5: 6000000 | D5: 48 | E5: 0 | F5: =IF($A5="","",IFERROR(($C5-$E5)/$D5,0)) | G5: =IF($A5="","",IFERROR(DATEDIF($B5,TODAY(),"m"),0)) | H5: =IF($A5="","",MIN($C5-$E5,$F5*$G5)) | I5: =IF($A5="","",$C5-$H5)
F6: =IF($A6="","",IFERROR(($C6-$E6)/$D6,0)) | G6: =IF($A6="","",IFERROR(DATEDIF($B6,TODAY(),"m"),0)) | H6: =IF($A6="","",MIN($C6-$E6,$F6*$G6)) | I6: =IF($A6="","",$C6-$H6)
F7: =IF($A7="","",IFERROR(($C7-$E7)/$D7,0)) | G7: =IF($A7="","",IFERROR(DATEDIF($B7,TODAY(),"m"),0)) | H7: =IF($A7="","",MIN($C7-$E7,$F7*$G7)) | I7: =IF($A7="","",$C7-$H7)
F8: =IF($A8="","",IFERROR(($C8-$E8)/$D8,0)) | G8: =IF($A8="","",IFERROR(DATEDIF($B8,TODAY(),"m"),0)) | H8: =IF($A8="","",MIN($C8-$E8,$F8*$G8)) | I8: =IF($A8="","",$C8-$H8)
F9: =IF($A9="","",IFERROR(($C9-$E9)/$D9,0)) | G9: =IF($A9="","",IFERROR(DATEDIF($B9,TODAY(),"m"),0)) | H9: =IF($A9="","",MIN($C9-$E9,$F9*$G9)) | I9: =IF($A9="","",$C9-$H9)
F10: =IF($A10="","",IFERROR(($C10-$E10)/$D10,0)) | G10: =IF($A10="","",IFERROR(DATEDIF($B10,TODAY(),"m"),0)) | H10: =IF($A10="","",MIN($C10-$E10,$F10*$G10)) | I10: =IF($A10="","",$C10-$H10)
F11: =IF($A11="","",IFERROR(($C11-$E11)/$D11,0)) | G11: =IF($A11="","",IFERROR(DATEDIF($B11,TODAY(),"m"),0)) | H11: =IF($A11="","",MIN($C11-$E11,$F11*$G11)) | I11: =IF($A11="","",$C11-$H11)
F12: =IF($A12="","",IFERROR(($C12-$E12)/$D12,0)) | G12: =IF($A12="","",IFERROR(DATEDIF($B12,TODAY(),"m"),0)) | H12: =IF($A12="","",MIN($C12-$E12,$F12*$G12)) | I12: =IF($A12="","",$C12-$H12)
F13: =IF($A13="","",IFERROR(($C13-$E13)/$D13,0)) | G13: =IF($A13="","",IFERROR(DATEDIF($B13,TODAY(),"m"),0)) | H13: =IF($A13="","",MIN($C13-$E13,$F13*$G13)) | I13: =IF($A13="","",$C13-$H13)
F14: =IF($A14="","",IFERROR(($C14-$E14)/$D14,0)) | G14: =IF($A14="","",IFERROR(DATEDIF($B14,TODAY(),"m"),0)) | H14: =IF($A14="","",MIN($C14-$E14,$F14*$G14)) | I14: =IF($A14="","",$C14-$H14)
F15: =IF($A15="","",IFERROR(($C15-$E15)/$D15,0)) | G15: =IF($A15="","",IFERROR(DATEDIF($B15,TODAY(),"m"),0)) | H15: =IF($A15="","",MIN($C15-$E15,$F15*$G15)) | I15: =IF($A15="","",$C15-$H15)
F16: =IF($A16="","",IFERROR(($C16-$E16)/$D16,0)) | G16: =IF($A16="","",IFERROR(DATEDIF($B16,TODAY(),"m"),0)) | H16: =IF($A16="","",MIN($C16-$E16,$F16*$G16)) | I16: =IF($A16="","",$C16-$H16)
F17: =IF($A17="","",IFERROR(($C17-$E17)/$D17,0)) | G17: =IF($A17="","",IFERROR(DATEDIF($B17,TODAY(),"m"),0)) | H17: =IF($A17="","",MIN($C17-$E17,$F17*$G17)) | I17: =IF($A17="","",$C17-$H17)
... F51: =IF($A51="","",IFERROR(($C51-$E51)/$D51,0)) | G51: =IF($A51="","",IFERROR(DATEDIF($B51,TODAY(),"m"),0)) | H51: =IF($A51="","",MIN($C51-$E51,$F51*$G51)) | I51: =IF($A51="","",$C51-$H51)

Sheet M_Batch
A1: Kode Batch | B1: Keterangan | C1: Kandang | D1: Tgl Mulai | E1: Tgl Selesai | F1: Status | G1: Lama (hari) | H1: Lama (bln) | I1: Jumlah Sapi | J1: Total Cattle-days | K1: Biaya Pakan | L1: Biaya Operasional | M1: Penyusutan | N1: Total Biaya Batch
A2: B001 | B2: Batch Penggemukan #1 | C2: K1 | D2: 45839 | F2: =IF($A2="","",IF($E2="","Aktif","Tutup")) | G2: =IF($A2="","",IF($D2="","",IF($E2="",TODAY()-$D2,$E2-$D2))) | H2: =IF($A2="","",IFERROR($G2/30,0)) | I2: =IF($A2="","",COUNTIF(M_Sapi!$F$2:$F$501,$A2)) | J2: =IF($A2="","",SUMIFS(M_Sapi!$L$2:$L$501,M_Sapi!$F$2:$F$501,$A2)) | K2: =IF($A2="","",SUMIFS(Pakan_Keluar!$F$2:$F$10001,Pakan_Keluar!$B$2:$B$10001,$A2)) | L2: =IF($A2="","",SUMIFS(Operasional!$D$2:$D$3001,Operasional!$B$2:$B$3001,$A2)) | M2: =IF($A2="","",SUM(M_AsetTetap!$F$2:$F$51)*$H2) | N2: =IF($A2="","",$K2+$L2+$M2)
F3: =IF($A3="","",IF($E3="","Aktif","Tutup")) | G3: =IF($A3="","",IF($D3="","",IF($E3="",TODAY()-$D3,$E3-$D3))) | H3: =IF($A3="","",IFERROR($G3/30,0)) | I3: =IF($A3="","",COUNTIF(M_Sapi!$F$2:$F$501,$A3)) | J3: =IF($A3="","",SUMIFS(M_Sapi!$L$2:$L$501,M_Sapi!$F$2:$F$501,$A3)) | K3: =IF($A3="","",SUMIFS(Pakan_Keluar!$F$2:$F$10001,Pakan_Keluar!$B$2:$B$10001,$A3)) | L3: =IF($A3="","",SUMIFS(Operasional!$D$2:$D$3001,Operasional!$B$2:$B$3001,$A3)) | M3: =IF($A3="","",SUM(M_AsetTetap!$F$2:$F$51)*$H3) | N3: =IF($A3="","",$K3+$L3+$M3)
F4: =IF($A4="","",IF($E4="","Aktif","Tutup")) | G4: =IF($A4="","",IF($D4="","",IF($E4="",TODAY()-$D4,$E4-$D4))) | H4: =IF($A4="","",IFERROR($G4/30,0)) | I4: =IF($A4="","",COUNTIF(M_Sapi!$F$2:$F$501,$A4)) | J4: =IF($A4="","",SUMIFS(M_Sapi!$L$2:$L$501,M_Sapi!$F$2:$F$501,$A4)) | K4: =IF($A4="","",SUMIFS(Pakan_Keluar!$F$2:$F$10001,Pakan_Keluar!$B$2:$B$10001,$A4)) | L4: =IF($A4="","",SUMIFS(Operasional!$D$2:$D$3001,Operasional!$B$2:$B$3001,$A4)) | M4: =IF($A4="","",SUM(M_AsetTetap!$F$2:$F$51)*$H4) | N4: =IF($A4="","",$K4+$L4+$M4)
F5: =IF($A5="","",IF($E5="","Aktif","Tutup")) | G5: =IF($A5="","",IF($D5="","",IF($E5="",TODAY()-$D5,$E5-$D5))) | H5: =IF($A5="","",IFERROR($G5/30,0)) | I5: =IF($A5="","",COUNTIF(M_Sapi!$F$2:$F$501,$A5)) | J5: =IF($A5="","",SUMIFS(M_Sapi!$L$2:$L$501,M_Sapi!$F$2:$F$501,$A5)) | K5: =IF($A5="","",SUMIFS(Pakan_Keluar!$F$2:$F$10001,Pakan_Keluar!$B$2:$B$10001,$A5)) | L5: =IF($A5="","",SUMIFS(Operasional!$D$2:$D$3001,Operasional!$B$2:$B$3001,$A5)) | M5: =IF($A5="","",SUM(M_AsetTetap!$F$2:$F$51)*$H5) | N5: =IF($A5="","",$K5+$L5+$M5)
F6: =IF($A6="","",IF($E6="","Aktif","Tutup")) | G6: =IF($A6="","",IF($D6="","",IF($E6="",TODAY()-$D6,$E6-$D6))) | H6: =IF($A6="","",IFERROR($G6/30,0)) | I6: =IF($A6="","",COUNTIF(M_Sapi!$F$2:$F$501,$A6)) | J6: =IF($A6="","",SUMIFS(M_Sapi!$L$2:$L$501,M_Sapi!$F$2:$F$501,$A6)) | K6: =IF($A6="","",SUMIFS(Pakan_Keluar!$F$2:$F$10001,Pakan_Keluar!$B$2:$B$10001,$A6)) | L6: =IF($A6="","",SUMIFS(Operasional!$D$2:$D$3001,Operasional!$B$2:$B$3001,$A6)) | M6: =IF($A6="","",SUM(M_AsetTetap!$F$2:$F$51)*$H6) | N6: =IF($A6="","",$K6+$L6+$M6)
F7: =IF($A7="","",IF($E7="","Aktif","Tutup")) | G7: =IF($A7="","",IF($D7="","",IF($E7="",TODAY()-$D7,$E7-$D7))) | H7: =IF($A7="","",IFERROR($G7/30,0)) | I7: =IF($A7="","",COUNTIF(M_Sapi!$F$2:$F$501,$A7)) | J7: =IF($A7="","",SUMIFS(M_Sapi!$L$2:$L$501,M_Sapi!$F$2:$F$501,$A7)) | K7: =IF($A7="","",SUMIFS(Pakan_Keluar!$F$2:$F$10001,Pakan_Keluar!$B$2:$B$10001,$A7)) | L7: =IF($A7="","",SUMIFS(Operasional!$D$2:$D$3001,Operasional!$B$2:$B$3001,$A7)) | M7: =IF($A7="","",SUM(M_AsetTetap!$F$2:$F$51)*$H7) | N7: =IF($A7="","",$K7+$L7+$M7)
F8: =IF($A8="","",IF($E8="","Aktif","Tutup")) | G8: =IF($A8="","",IF($D8="","",IF($E8="",TODAY()-$D8,$E8-$D8))) | H8: =IF($A8="","",IFERROR($G8/30,0)) | I8: =IF($A8="","",COUNTIF(M_Sapi!$F$2:$F$501,$A8)) | J8: =IF($A8="","",SUMIFS(M_Sapi!$L$2:$L$501,M_Sapi!$F$2:$F$501,$A8)) | K8: =IF($A8="","",SUMIFS(Pakan_Keluar!$F$2:$F$10001,Pakan_Keluar!$B$2:$B$10001,$A8)) | L8: =IF($A8="","",SUMIFS(Operasional!$D$2:$D$3001,Operasional!$B$2:$B$3001,$A8)) | M8: =IF($A8="","",SUM(M_AsetTetap!$F$2:$F$51)*$H8) | N8: =IF($A8="","",$K8+$L8+$M8)
F9: =IF($A9="","",IF($E9="","Aktif","Tutup")) | G9: =IF($A9="","",IF($D9="","",IF($E9="",TODAY()-$D9,$E9-$D9))) | H9: =IF($A9="","",IFERROR($G9/30,0)) | I9: =IF($A9="","",COUNTIF(M_Sapi!$F$2:$F$501,$A9)) | J9: =IF($A9="","",SUMIFS(M_Sapi!$L$2:$L$501,M_Sapi!$F$2:$F$501,$A9)) | K9: =IF($A9="","",SUMIFS(Pakan_Keluar!$F$2:$F$10001,Pakan_Keluar!$B$2:$B$10001,$A9)) | L9: =IF($A9="","",SUMIFS(Operasional!$D$2:$D$3001,Operasional!$B$2:$B$3001,$A9)) | M9: =IF($A9="","",SUM(M_AsetTetap!$F$2:$F$51)*$H9) | N9: =IF($A9="","",$K9+$L9+$M9)
F10: =IF($A10="","",IF($E10="","Aktif","Tutup")) | G10: =IF($A10="","",IF($D10="","",IF($E10="",TODAY()-$D10,$E10-$D10))) | H10: =IF($A10="","",IFERROR($G10/30,0)) | I10: =IF($A10="","",COUNTIF(M_Sapi!$F$2:$F$501,$A10)) | J10: =IF($A10="","",SUMIFS(M_Sapi!$L$2:$L$501,M_Sapi!$F$2:$F$501,$A10)) | K10: =IF($A10="","",SUMIFS(Pakan_Keluar!$F$2:$F$10001,Pakan_Keluar!$B$2:$B$10001,$A10)) | L10: =IF($A10="","",SUMIFS(Operasional!$D$2:$D$3001,Operasional!$B$2:$B$3001,$A10)) | M10: =IF($A10="","",SUM(M_AsetTetap!$F$2:$F$51)*$H10) | N10: =IF($A10="","",$K10+$L10+$M10)
F11: =IF($A11="","",IF($E11="","Aktif","Tutup")) | G11: =IF($A11="","",IF($D11="","",IF($E11="",TODAY()-$D11,$E11-$D11))) | H11: =IF($A11="","",IFERROR($G11/30,0)) | I11: =IF($A11="","",COUNTIF(M_Sapi!$F$2:$F$501,$A11)) | J11: =IF($A11="","",SUMIFS(M_Sapi!$L$2:$L$501,M_Sapi!$F$2:$F$501,$A11)) | K11: =IF($A11="","",SUMIFS(Pakan_Keluar!$F$2:$F$10001,Pakan_Keluar!$B$2:$B$10001,$A11)) | L11: =IF($A11="","",SUMIFS(Operasional!$D$2:$D$3001,Operasional!$B$2:$B$3001,$A11)) | M11: =IF($A11="","",SUM(M_AsetTetap!$F$2:$F$51)*$H11) | N11: =IF($A11="","",$K11+$L11+$M11)
F12: =IF($A12="","",IF($E12="","Aktif","Tutup")) | G12: =IF($A12="","",IF($D12="","",IF($E12="",TODAY()-$D12,$E12-$D12))) | H12: =IF($A12="","",IFERROR($G12/30,0)) | I12: =IF($A12="","",COUNTIF(M_Sapi!$F$2:$F$501,$A12)) | J12: =IF($A12="","",SUMIFS(M_Sapi!$L$2:$L$501,M_Sapi!$F$2:$F$501,$A12)) | K12: =IF($A12="","",SUMIFS(Pakan_Keluar!$F$2:$F$10001,Pakan_Keluar!$B$2:$B$10001,$A12)) | L12: =IF($A12="","",SUMIFS(Operasional!$D$2:$D$3001,Operasional!$B$2:$B$3001,$A12)) | M12: =IF($A12="","",SUM(M_AsetTetap!$F$2:$F$51)*$H12) | N12: =IF($A12="","",$K12+$L12+$M12)
F13: =IF($A13="","",IF($E13="","Aktif","Tutup")) | G13: =IF($A13="","",IF($D13="","",IF($E13="",TODAY()-$D13,$E13-$D13))) | H13: =IF($A13="","",IFERROR($G13/30,0)) | I13: =IF($A13="","",COUNTIF(M_Sapi!$F$2:$F$501,$A13)) | J13: =IF($A13="","",SUMIFS(M_Sapi!$L$2:$L$501,M_Sapi!$F$2:$F$501,$A13)) | K13: =IF($A13="","",SUMIFS(Pakan_Keluar!$F$2:$F$10001,Pakan_Keluar!$B$2:$B$10001,$A13)) | L13: =IF($A13="","",SUMIFS(Operasional!$D$2:$D$3001,Operasional!$B$2:$B$3001,$A13)) | M13: =IF($A13="","",SUM(M_AsetTetap!$F$2:$F$51)*$H13) | N13: =IF($A13="","",$K13+$L13+$M13)
F14: =IF($A14="","",IF($E14="","Aktif","Tutup")) | G14: =IF($A14="","",IF($D14="","",IF($E14="",TODAY()-$D14,$E14-$D14))) | H14: =IF($A14="","",IFERROR($G14/30,0)) | I14: =IF($A14="","",COUNTIF(M_Sapi!$F$2:$F$501,$A14)) | J14: =IF($A14="","",SUMIFS(M_Sapi!$L$2:$L$501,M_Sapi!$F$2:$F$501,$A14)) | K14: =IF($A14="","",SUMIFS(Pakan_Keluar!$F$2:$F$10001,Pakan_Keluar!$B$2:$B$10001,$A14)) | L14: =IF($A14="","",SUMIFS(Operasional!$D$2:$D$3001,Operasional!$B$2:$B$3001,$A14)) | M14: =IF($A14="","",SUM(M_AsetTetap!$F$2:$F$51)*$H14) | N14: =IF($A14="","",$K14+$L14+$M14)
... F201: =IF($A201="","",IF($E201="","Aktif","Tutup")) | G201: =IF($A201="","",IF($D201="","",IF($E201="",TODAY()-$D201,$E201-$D201))) | H201: =IF($A201="","",IFERROR($G201/30,0)) | I201: =IF($A201="","",COUNTIF(M_Sapi!$F$2:$F$501,$A201)) | J201: =IF($A201="","",SUMIFS(M_Sapi!$L$2:$L$501,M_Sapi!$F$2:$F$501,$A201)) | K201: =IF($A201="","",SUMIFS(Pakan_Keluar!$F$2:$F$10001,Pakan_Keluar!$B$2:$B$10001,$A201)) | L201: =IF($A201="","",SUMIFS(Operasional!$D$2:$D$3001,Operasional!$B$2:$B$3001,$A201)) | M201: =IF($A201="","",SUM(M_AsetTetap!$F$2:$F$51)*$H201) | N201: =IF($A201="","",$K201+$L201+$M201)

Sheet M_Sapi
A1: ID Sapi | B1: Tgl Masuk | C1: Bangsa | D1: Bobot Awal | E1: Harga Beli | F1: Batch | G1: Status Input | H1: Tgl Mati | I1: Terjual? | J1: Status | K1: Tgl Keluar | L1: Hari Pelihara
A2: S001 | B2: 45901 | C2: Limousin | D2: 280 | E2: 28000000 | F2: B001 | G2: Aktif | I2: =IF($A2="","",COUNTIF(Penjualan!$B$2:$B$1001,$A2)) | J2: =IF($A2="","",IF($I2>0,"Terjual",IF($G2="Mati","Mati","Aktif"))) | K2: =IF($A2="","",IF($I2>0,INDEX(Penjualan!$A$2:$A$1001,MATCH($A2,Penjualan!$B$2:$B$1001,0)),IF($G2="Mati",$H2,""))) | L2: =IF($A2="","",IF($K2="",TODAY()-$B2,$K2-$B2))
A3: S002 | B3: 45901 | C3: Simental | D3: 290 | E3: 29500000 | F3: B001 | G3: Aktif | I3: =IF($A3="","",COUNTIF(Penjualan!$B$2:$B$1001,$A3)) | J3: =IF($A3="","",IF($I3>0,"Terjual",IF($G3="Mati","Mati","Aktif"))) | K3: =IF($A3="","",IF($I3>0,INDEX(Penjualan!$A$2:$A$1001,MATCH($A3,Penjualan!$B$2:$B$1001,0)),IF($G3="Mati",$H3,""))) | L3: =IF($A3="","",IF($K3="",TODAY()-$B3,$K3-$B3))
A4: S003 | B4: 45884 | C4: PO | D4: 330 | E4: 31000000 | F4: B001 | G4: Aktif | I4: =IF($A4="","",COUNTIF(Penjualan!$B$2:$B$1001,$A4)) | J4: =IF($A4="","",IF($I4>0,"Terjual",IF($G4="Mati","Mati","Aktif"))) | K4: =IF($A4="","",IF($I4>0,INDEX(Penjualan!$A$2:$A$1001,MATCH($A4,Penjualan!$B$2:$B$1001,0)),IF($G4="Mati",$H4,""))) | L4: =IF($A4="","",IF($K4="",TODAY()-$B4,$K4-$B4))
A5: S004 | B5: 45884 | C5: Brahman | D5: 345 | E5: 33000000 | F5: B001 | G5: Aktif | I5: =IF($A5="","",COUNTIF(Penjualan!$B$2:$B$1001,$A5)) | J5: =IF($A5="","",IF($I5>0,"Terjual",IF($G5="Mati","Mati","Aktif"))) | K5: =IF($A5="","",IF($I5>0,INDEX(Penjualan!$A$2:$A$1001,MATCH($A5,Penjualan!$B$2:$B$1001,0)),IF($G5="Mati",$H5,""))) | L5: =IF($A5="","",IF($K5="",TODAY()-$B5,$K5-$B5))
A6: S005 | B6: 45839 | C6: Limousin | D6: 410 | E6: 41000000 | F6: B001 | G6: Aktif | I6: =IF($A6="","",COUNTIF(Penjualan!$B$2:$B$1001,$A6)) | J6: =IF($A6="","",IF($I6>0,"Terjual",IF($G6="Mati","Mati","Aktif"))) | K6: =IF($A6="","",IF($I6>0,INDEX(Penjualan!$A$2:$A$1001,MATCH($A6,Penjualan!$B$2:$B$1001,0)),IF($G6="Mati",$H6,""))) | L6: =IF($A6="","",IF($K6="",TODAY()-$B6,$K6-$B6))
A7: S006 | B7: 45839 | C7: Simental | D7: 420 | E7: 42500000 | F7: B001 | G7: Mati | H7: 46037 | I7: =IF($A7="","",COUNTIF(Penjualan!$B$2:$B$1001,$A7)) | J7: =IF($A7="","",IF($I7>0,"Terjual",IF($G7="Mati","Mati","Aktif"))) | K7: =IF($A7="","",IF($I7>0,INDEX(Penjualan!$A$2:$A$1001,MATCH($A7,Penjualan!$B$2:$B$1001,0)),IF($G7="Mati",$H7,""))) | L7: =IF($A7="","",IF($K7="",TODAY()-$B7,$K7-$B7))
I8: =IF($A8="","",COUNTIF(Penjualan!$B$2:$B$1001,$A8)) | J8: =IF($A8="","",IF($I8>0,"Terjual",IF($G8="Mati","Mati","Aktif"))) | K8: =IF($A8="","",IF($I8>0,INDEX(Penjualan!$A$2:$A$1001,MATCH($A8,Penjualan!$B$2:$B$1001,0)),IF($G8="Mati",$H8,""))) | L8: =IF($A8="","",IF($K8="",TODAY()-$B8,$K8-$B8))
I9: =IF($A9="","",COUNTIF(Penjualan!$B$2:$B$1001,$A9)) | J9: =IF($A9="","",IF($I9>0,"Terjual",IF($G9="Mati","Mati","Aktif"))) | K9: =IF($A9="","",IF($I9>0,INDEX(Penjualan!$A$2:$A$1001,MATCH($A9,Penjualan!$B$2:$B$1001,0)),IF($G9="Mati",$H9,""))) | L9: =IF($A9="","",IF($K9="",TODAY()-$B9,$K9-$B9))
I10: =IF($A10="","",COUNTIF(Penjualan!$B$2:$B$1001,$A10)) | J10: =IF($A10="","",IF($I10>0,"Terjual",IF($G10="Mati","Mati","Aktif"))) | K10: =IF($A10="","",IF($I10>0,INDEX(Penjualan!$A$2:$A$1001,MATCH($A10,Penjualan!$B$2:$B$1001,0)),IF($G10="Mati",$H10,""))) | L10: =IF($A10="","",IF($K10="",TODAY()-$B10,$K10-$B10))
I11: =IF($A11="","",COUNTIF(Penjualan!$B$2:$B$1001,$A11)) | J11: =IF($A11="","",IF($I11>0,"Terjual",IF($G11="Mati","Mati","Aktif"))) | K11: =IF($A11="","",IF($I11>0,INDEX(Penjualan!$A$2:$A$1001,MATCH($A11,Penjualan!$B$2:$B$1001,0)),IF($G11="Mati",$H11,""))) | L11: =IF($A11="","",IF($K11="",TODAY()-$B11,$K11-$B11))
I12: =IF($A12="","",COUNTIF(Penjualan!$B$2:$B$1001,$A12)) | J12: =IF($A12="","",IF($I12>0,"Terjual",IF($G12="Mati","Mati","Aktif"))) | K12: =IF($A12="","",IF($I12>0,INDEX(Penjualan!$A$2:$A$1001,MATCH($A12,Penjualan!$B$2:$B$1001,0)),IF($G12="Mati",$H12,""))) | L12: =IF($A12="","",IF($K12="",TODAY()-$B12,$K12-$B12))
I13: =IF($A13="","",COUNTIF(Penjualan!$B$2:$B$1001,$A13)) | J13: =IF($A13="","",IF($I13>0,"Terjual",IF($G13="Mati","Mati","Aktif"))) | K13: =IF($A13="","",IF($I13>0,INDEX(Penjualan!$A$2:$A$1001,MATCH($A13,Penjualan!$B$2:$B$1001,0)),IF($G13="Mati",$H13,""))) | L13: =IF($A13="","",IF($K13="",TODAY()-$B13,$K13-$B13))
I14: =IF($A14="","",COUNTIF(Penjualan!$B$2:$B$1001,$A14)) | J14: =IF($A14="","",IF($I14>0,"Terjual",IF($G14="Mati","Mati","Aktif"))) | K14: =IF($A14="","",IF($I14>0,INDEX(Penjualan!$A$2:$A$1001,MATCH($A14,Penjualan!$B$2:$B$1001,0)),IF($G14="Mati",$H14,""))) | L14: =IF($A14="","",IF($K14="",TODAY()-$B14,$K14-$B14))
I15: =IF($A15="","",COUNTIF(Penjualan!$B$2:$B$1001,$A15)) | J15: =IF($A15="","",IF($I15>0,"Terjual",IF($G15="Mati","Mati","Aktif"))) | K15: =IF($A15="","",IF($I15>0,INDEX(Penjualan!$A$2:$A$1001,MATCH($A15,Penjualan!$B$2:$B$1001,0)),IF($G15="Mati",$H15,""))) | L15: =IF($A15="","",IF($K15="",TODAY()-$B15,$K15-$B15))
I16: =IF($A16="","",COUNTIF(Penjualan!$B$2:$B$1001,$A16)) | J16: =IF($A16="","",IF($I16>0,"Terjual",IF($G16="Mati","Mati","Aktif"))) | K16: =IF($A16="","",IF($I16>0,INDEX(Penjualan!$A$2:$A$1001,MATCH($A16,Penjualan!$B$2:$B$1001,0)),IF($G16="Mati",$H16,""))) | L16: =IF($A16="","",IF($K16="",TODAY()-$B16,$K16-$B16))
I17: =IF($A17="","",COUNTIF(Penjualan!$B$2:$B$1001,$A17)) | J17: =IF($A17="","",IF($I17>0,"Terjual",IF($G17="Mati","Mati","Aktif"))) | K17: =IF($A17="","",IF($I17>0,INDEX(Penjualan!$A$2:$A$1001,MATCH($A17,Penjualan!$B$2:$B$1001,0)),IF($G17="Mati",$H17,""))) | L17: =IF($A17="","",IF($K17="",TODAY()-$B17,$K17-$B17))
I18: =IF($A18="","",COUNTIF(Penjualan!$B$2:$B$1001,$A18)) | J18: =IF($A18="","",IF($I18>0,"Terjual",IF($G18="Mati","Mati","Aktif"))) | K18: =IF($A18="","",IF($I18>0,INDEX(Penjualan!$A$2:$A$1001,MATCH($A18,Penjualan!$B$2:$B$1001,0)),IF($G18="Mati",$H18,""))) | L18: =IF($A18="","",IF($K18="",TODAY()-$B18,$K18-$B18))
I19: =IF($A19="","",COUNTIF(Penjualan!$B$2:$B$1001,$A19)) | J19: =IF($A19="","",IF($I19>0,"Terjual",IF($G19="Mati","Mati","Aktif"))) | K19: =IF($A19="","",IF($I19>0,INDEX(Penjualan!$A$2:$A$1001,MATCH($A19,Penjualan!$B$2:$B$1001,0)),IF($G19="Mati",$H19,""))) | L19: =IF($A19="","",IF($K19="",TODAY()-$B19,$K19-$B19))
... I501: =IF($A501="","",COUNTIF(Penjualan!$B$2:$B$1001,$A501)) | J501: =IF($A501="","",IF($I501>0,"Terjual",IF($G501="Mati","Mati","Aktif"))) | K501: =IF($A501="","",IF($I501>0,INDEX(Penjualan!$A$2:$A$1001,MATCH($A501,Penjualan!$B$2:$B$1001,0)),IF($G501="Mati",$H501,""))) | L501: =IF($A501="","",IF($K501="",TODAY()-$B501,$K501-$B501))

Sheet Pakan_Masuk
A1: Tgl | B1: Kode Pakan | C1: Qty (kg) | D1: Harga Total | E1: Harga/kg
A2: 45901 | B2: PK01 | C2: 3000 | D2: 1500000 | E2: =IF($C2="","",IFERROR($D2/$C2,0))
A3: 45901 | B3: PK02 | C3: 1000 | D3: 3500000 | E3: =IF($C3="","",IFERROR($D3/$C3,0))
A4: 45905 | B4: PK03 | C4: 50 | D4: 750000 | E4: =IF($C4="","",IFERROR($D4/$C4,0))
A5: 45915 | B5: PK01 | C5: 3000 | D5: 1560000 | E5: =IF($C5="","",IFERROR($D5/$C5,0))
A6: 45920 | B6: PK02 | C6: 1200 | D6: 4320000 | E6: =IF($C6="","",IFERROR($D6/$C6,0))
E7: =IF($C7="","",IFERROR($D7/$C7,0))
E8: =IF($C8="","",IFERROR($D8/$C8,0))
E9: =IF($C9="","",IFERROR($D9/$C9,0))
E10: =IF($C10="","",IFERROR($D10/$C10,0))
E11: =IF($C11="","",IFERROR($D11/$C11,0))
E12: =IF($C12="","",IFERROR($D12/$C12,0))
E13: =IF($C13="","",IFERROR($D13/$C13,0))
E14: =IF($C14="","",IFERROR($D14/$C14,0))
E15: =IF($C15="","",IFERROR($D15/$C15,0))
E16: =IF($C16="","",IFERROR($D16/$C16,0))
E17: =IF($C17="","",IFERROR($D17/$C17,0))
E18: =IF($C18="","",IFERROR($D18/$C18,0))
... E3001: =IF($C3001="","",IFERROR($D3001/$C3001,0))

Sheet Pakan_Keluar
A1: Tgl | B1: Batch | C1: Kode Pakan | D1: Qty (kg) | E1: Harga Rata2/kg | F1: Nilai Konsumsi
A2: 45902 | B2: B001 | C2: PK01 | D2: 40 | E2: =IF($C2="","",IFERROR(SUMIFS(Pakan_Masuk!$D$2:$D$3001,Pakan_Masuk!$B$2:$B$3001,$C2)/SUMIFS(Pakan_Masuk!$C$2:$C$3001,Pakan_Masuk!$B$2:$B$3001,$C2),0)) | F2: =IF($C2="","",$D2*$E2)
A3: 45902 | B3: B001 | C3: PK02 | D3: 12 | E3: =IF($C3="","",IFERROR(SUMIFS(Pakan_Masuk!$D$2:$D$3001,Pakan_Masuk!$B$2:$B$3001,$C3)/SUMIFS(Pakan_Masuk!$C$2:$C$3001,Pakan_Masuk!$B$2:$B$3001,$C3),0)) | F3: =IF($C3="","",$D3*$E3)
A4: 45902 | B4: B001 | C4: PK01 | D4: 45 | E4: =IF($C4="","",IFERROR(SUMIFS(Pakan_Masuk!$D$2:$D$3001,Pakan_Masuk!$B$2:$B$3001,$C4)/SUMIFS(Pakan_Masuk!$C$2:$C$3001,Pakan_Masuk!$B$2:$B$3001,$C4),0)) | F4: =IF($C4="","",$D4*$E4)
A5: 45902 | B5: B001 | C5: PK02 | D5: 14 | E5: =IF($C5="","",IFERROR(SUMIFS(Pakan_Masuk!$D$2:$D$3001,Pakan_Masuk!$B$2:$B$3001,$C5)/SUMIFS(Pakan_Masuk!$C$2:$C$3001,Pakan_Masuk!$B$2:$B$3001,$C5),0)) | F5: =IF($C5="","",$D5*$E5)
A6: 45902 | B6: B001 | C6: PK01 | D6: 55 | E6: =IF($C6="","",IFERROR(SUMIFS(Pakan_Masuk!$D$2:$D$3001,Pakan_Masuk!$B$2:$B$3001,$C6)/SUMIFS(Pakan_Masuk!$C$2:$C$3001,Pakan_Masuk!$B$2:$B$3001,$C6),0)) | F6: =IF($C6="","",$D6*$E6)
A7: 45902 | B7: B001 | C7: PK02 | D7: 18 | E7: =IF($C7="","",IFERROR(SUMIFS(Pakan_Masuk!$D$2:$D$3001,Pakan_Masuk!$B$2:$B$3001,$C7)/SUMIFS(Pakan_Masuk!$C$2:$C$3001,Pakan_Masuk!$B$2:$B$3001,$C7),0)) | F7: =IF($C7="","",$D7*$E7)
E8: =IF($C8="","",IFERROR(SUMIFS(Pakan_Masuk!$D$2:$D$3001,Pakan_Masuk!$B$2:$B$3001,$C8)/SUMIFS(Pakan_Masuk!$C$2:$C$3001,Pakan_Masuk!$B$2:$B$3001,$C8),0)) | F8: =IF($C8="","",$D8*$E8)
E9: =IF($C9="","",IFERROR(SUMIFS(Pakan_Masuk!$D$2:$D$3001,Pakan_Masuk!$B$2:$B$3001,$C9)/SUMIFS(Pakan_Masuk!$C$2:$C$3001,Pakan_Masuk!$B$2:$B$3001,$C9),0)) | F9: =IF($C9="","",$D9*$E9)
E10: =IF($C10="","",IFERROR(SUMIFS(Pakan_Masuk!$D$2:$D$3001,Pakan_Masuk!$B$2:$B$3001,$C10)/SUMIFS(Pakan_Masuk!$C$2:$C$3001,Pakan_Masuk!$B$2:$B$3001,$C10),0)) | F10: =IF($C10="","",$D10*$E10)
E11: =IF($C11="","",IFERROR(SUMIFS(Pakan_Masuk!$D$2:$D$3001,Pakan_Masuk!$B$2:$B$3001,$C11)/SUMIFS(Pakan_Masuk!$C$2:$C$3001,Pakan_Masuk!$B$2:$B$3001,$C11),0)) | F11: =IF($C11="","",$D11*$E11)
E12: =IF($C12="","",IFERROR(SUMIFS(Pakan_Masuk!$D$2:$D$3001,Pakan_Masuk!$B$2:$B$3001,$C12)/SUMIFS(Pakan_Masuk!$C$2:$C$3001,Pakan_Masuk!$B$2:$B$3001,$C12),0)) | F12: =IF($C12="","",$D12*$E12)
E13: =IF($C13="","",IFERROR(SUMIFS(Pakan_Masuk!$D$2:$D$3001,Pakan_Masuk!$B$2:$B$3001,$C13)/SUMIFS(Pakan_Masuk!$C$2:$C$3001,Pakan_Masuk!$B$2:$B$3001,$C13),0)) | F13: =IF($C13="","",$D13*$E13)
E14: =IF($C14="","",IFERROR(SUMIFS(Pakan_Masuk!$D$2:$D$3001,Pakan_Masuk!$B$2:$B$3001,$C14)/SUMIFS(Pakan_Masuk!$C$2:$C$3001,Pakan_Masuk!$B$2:$B$3001,$C14),0)) | F14: =IF($C14="","",$D14*$E14)
E15: =IF($C15="","",IFERROR(SUMIFS(Pakan_Masuk!$D$2:$D$3001,Pakan_Masuk!$B$2:$B$3001,$C15)/SUMIFS(Pakan_Masuk!$C$2:$C$3001,Pakan_Masuk!$B$2:$B$3001,$C15),0)) | F15: =IF($C15="","",$D15*$E15)
E16: =IF($C16="","",IFERROR(SUMIFS(Pakan_Masuk!$D$2:$D$3001,Pakan_Masuk!$B$2:$B$3001,$C16)/SUMIFS(Pakan_Masuk!$C$2:$C$3001,Pakan_Masuk!$B$2:$B$3001,$C16),0)) | F16: =IF($C16="","",$D16*$E16)
E17: =IF($C17="","",IFERROR(SUMIFS(Pakan_Masuk!$D$2:$D$3001,Pakan_Masuk!$B$2:$B$3001,$C17)/SUMIFS(Pakan_Masuk!$C$2:$C$3001,Pakan_Masuk!$B$2:$B$3001,$C17),0)) | F17: =IF($C17="","",$D17*$E17)
E18: =IF($C18="","",IFERROR(SUMIFS(Pakan_Masuk!$D$2:$D$3001,Pakan_Masuk!$B$2:$B$3001,$C18)/SUMIFS(Pakan_Masuk!$C$2:$C$3001,Pakan_Masuk!$B$2:$B$3001,$C18),0)) | F18: =IF($C18="","",$D18*$E18)
E19: =IF($C19="","",IFERROR(SUMIFS(Pakan_Masuk!$D$2:$D$3001,Pakan_Masuk!$B$2:$B$3001,$C19)/SUMIFS(Pakan_Masuk!$C$2:$C$3001,Pakan_Masuk!$B$2:$B$3001,$C19),0)) | F19: =IF($C19="","",$D19*$E19)
... E10001: =IF($C10001="","",IFERROR(SUMIFS(Pakan_Masuk!$D$2:$D$3001,Pakan_Masuk!$B$2:$B$3001,$C10001)/SUMIFS(Pakan_Masuk!$C$2:$C$3001,Pakan_Masuk!$B$2:$B$3001,$C10001),0)) | F10001: =IF($C10001="","",$D10001*$E10001)

Sheet Timbang
A1: ID Sapi | B1: Tgl Timbang | C1: Bobot (kg) | D1: Bobot Awal | E1: Tgl Masuk | F1: Pertambahan (kg) | G1: Hari | H1: ADG Kumulatif
A2: S001 | B2: 45931 | C2: 312 | D2: =IF($A2="","",IFERROR(VLOOKUP($A2,M_Sapi!$A$2:$D$501,4,0),"")) | E2: =IF($A2="","",IFERROR(VLOOKUP($A2,M_Sapi!$A$2:$B$501,2,0),"")) | F2: =IF(OR($A2="",$C2=""),"",$C2-$D2) | G2: =IF(OR($A2="",$B2=""),"",$B2-$E2) | H2: =IF(OR($G2="",$G2=0),"",$F2/$G2)
A3: S002 | B3: 45931 | C3: 325 | D3: =IF($A3="","",IFERROR(VLOOKUP($A3,M_Sapi!$A$2:$D$501,4,0),"")) | E3: =IF($A3="","",IFERROR(VLOOKUP($A3,M_Sapi!$A$2:$B$501,2,0),"")) | F3: =IF(OR($A3="",$C3=""),"",$C3-$D3) | G3: =IF(OR($A3="",$B3=""),"",$B3-$E3) | H3: =IF(OR($G3="",$G3=0),"",$F3/$G3)
A4: S003 | B4: 45931 | C4: 372 | D4: =IF($A4="","",IFERROR(VLOOKUP($A4,M_Sapi!$A$2:$D$501,4,0),"")) | E4: =IF($A4="","",IFERROR(VLOOKUP($A4,M_Sapi!$A$2:$B$501,2,0),"")) | F4: =IF(OR($A4="",$C4=""),"",$C4-$D4) | G4: =IF(OR($A4="",$B4=""),"",$B4-$E4) | H4: =IF(OR($G4="",$G4=0),"",$F4/$G4)
A5: S004 | B5: 45931 | C5: 388 | D5: =IF($A5="","",IFERROR(VLOOKUP($A5,M_Sapi!$A$2:$D$501,4,0),"")) | E5: =IF($A5="","",IFERROR(VLOOKUP($A5,M_Sapi!$A$2:$B$501,2,0),"")) | F5: =IF(OR($A5="",$C5=""),"",$C5-$D5) | G5: =IF(OR($A5="",$B5=""),"",$B5-$E5) | H5: =IF(OR($G5="",$G5=0),"",$F5/$G5)
A6: S005 | B6: 45931 | C6: 458 | D6: =IF($A6="","",IFERROR(VLOOKUP($A6,M_Sapi!$A$2:$D$501,4,0),"")) | E6: =IF($A6="","",IFERROR(VLOOKUP($A6,M_Sapi!$A$2:$B$501,2,0),"")) | F6: =IF(OR($A6="",$C6=""),"",$C6-$D6) | G6: =IF(OR($A6="",$B6=""),"",$B6-$E6) | H6: =IF(OR($G6="",$G6=0),"",$F6/$G6)
A7: S006 | B7: 45931 | C7: 470 | D7: =IF($A7="","",IFERROR(VLOOKUP($A7,M_Sapi!$A$2:$D$501,4,0),"")) | E7: =IF($A7="","",IFERROR(VLOOKUP($A7,M_Sapi!$A$2:$B$501,2,0),"")) | F7: =IF(OR($A7="",$C7=""),"",$C7-$D7) | G7: =IF(OR($A7="",$B7=""),"",$B7-$E7) | H7: =IF(OR($G7="",$G7=0),"",$F7/$G7)
D8: =IF($A8="","",IFERROR(VLOOKUP($A8,M_Sapi!$A$2:$D$501,4,0),"")) | E8: =IF($A8="","",IFERROR(VLOOKUP($A8,M_Sapi!$A$2:$B$501,2,0),"")) | F8: =IF(OR($A8="",$C8=""),"",$C8-$D8) | G8: =IF(OR($A8="",$B8=""),"",$B8-$E8) | H8: =IF(OR($G8="",$G8=0),"",$F8/$G8)
D9: =IF($A9="","",IFERROR(VLOOKUP($A9,M_Sapi!$A$2:$D$501,4,0),"")) | E9: =IF($A9="","",IFERROR(VLOOKUP($A9,M_Sapi!$A$2:$B$501,2,0),"")) | F9: =IF(OR($A9="",$C9=""),"",$C9-$D9) | G9: =IF(OR($A9="",$B9=""),"",$B9-$E9) | H9: =IF(OR($G9="",$G9=0),"",$F9/$G9)
D10: =IF($A10="","",IFERROR(VLOOKUP($A10,M_Sapi!$A$2:$D$501,4,0),"")) | E10: =IF($A10="","",IFERROR(VLOOKUP($A10,M_Sapi!$A$2:$B$501,2,0),"")) | F10: =IF(OR($A10="",$C10=""),"",$C10-$D10) | G10: =IF(OR($A10="",$B10=""),"",$B10-$E10) | H10: =IF(OR($G10="",$G10=0),"",$F10/$G10)
D11: =IF($A11="","",IFERROR(VLOOKUP($A11,M_Sapi!$A$2:$D$501,4,0),"")) | E11: =IF($A11="","",IFERROR(VLOOKUP($A11,M_Sapi!$A$2:$B$501,2,0),"")) | F11: =IF(OR($A11="",$C11=""),"",$C11-$D11) | G11: =IF(OR($A11="",$B11=""),"",$B11-$E11) | H11: =IF(OR($G11="",$G11=0),"",$F11/$G11)
D12: =IF($A12="","",IFERROR(VLOOKUP($A12,M_Sapi!$A$2:$D$501,4,0),"")) | E12: =IF($A12="","",IFERROR(VLOOKUP($A12,M_Sapi!$A$2:$B$501,2,0),"")) | F12: =IF(OR($A12="",$C12=""),"",$C12-$D12) | G12: =IF(OR($A12="",$B12=""),"",$B12-$E12) | H12: =IF(OR($G12="",$G12=0),"",$F12/$G12)
D13: =IF($A13="","",IFERROR(VLOOKUP($A13,M_Sapi!$A$2:$D$501,4,0),"")) | E13: =IF($A13="","",IFERROR(VLOOKUP($A13,M_Sapi!$A$2:$B$501,2,0),"")) | F13: =IF(OR($A13="",$C13=""),"",$C13-$D13) | G13: =IF(OR($A13="",$B13=""),"",$B13-$E13) | H13: =IF(OR($G13="",$G13=0),"",$F13/$G13)
D14: =IF($A14="","",IFERROR(VLOOKUP($A14,M_Sapi!$A$2:$D$501,4,0),"")) | E14: =IF($A14="","",IFERROR(VLOOKUP($A14,M_Sapi!$A$2:$B$501,2,0),"")) | F14: =IF(OR($A14="",$C14=""),"",$C14-$D14) | G14: =IF(OR($A14="",$B14=""),"",$B14-$E14) | H14: =IF(OR($G14="",$G14=0),"",$F14/$G14)
D15: =IF($A15="","",IFERROR(VLOOKUP($A15,M_Sapi!$A$2:$D$501,4,0),"")) | E15: =IF($A15="","",IFERROR(VLOOKUP($A15,M_Sapi!$A$2:$B$501,2,0),"")) | F15: =IF(OR($A15="",$C15=""),"",$C15-$D15) | G15: =IF(OR($A15="",$B15=""),"",$B15-$E15) | H15: =IF(OR($G15="",$G15=0),"",$F15/$G15)
D16: =IF($A16="","",IFERROR(VLOOKUP($A16,M_Sapi!$A$2:$D$501,4,0),"")) | E16: =IF($A16="","",IFERROR(VLOOKUP($A16,M_Sapi!$A$2:$B$501,2,0),"")) | F16: =IF(OR($A16="",$C16=""),"",$C16-$D16) | G16: =IF(OR($A16="",$B16=""),"",$B16-$E16) | H16: =IF(OR($G16="",$G16=0),"",$F16/$G16)
D17: =IF($A17="","",IFERROR(VLOOKUP($A17,M_Sapi!$A$2:$D$501,4,0),"")) | E17: =IF($A17="","",IFERROR(VLOOKUP($A17,M_Sapi!$A$2:$B$501,2,0),"")) | F17: =IF(OR($A17="",$C17=""),"",$C17-$D17) | G17: =IF(OR($A17="",$B17=""),"",$B17-$E17) | H17: =IF(OR($G17="",$G17=0),"",$F17/$G17)
D18: =IF($A18="","",IFERROR(VLOOKUP($A18,M_Sapi!$A$2:$D$501,4,0),"")) | E18: =IF($A18="","",IFERROR(VLOOKUP($A18,M_Sapi!$A$2:$B$501,2,0),"")) | F18: =IF(OR($A18="",$C18=""),"",$C18-$D18) | G18: =IF(OR($A18="",$B18=""),"",$B18-$E18) | H18: =IF(OR($G18="",$G18=0),"",$F18/$G18)
D19: =IF($A19="","",IFERROR(VLOOKUP($A19,M_Sapi!$A$2:$D$501,4,0),"")) | E19: =IF($A19="","",IFERROR(VLOOKUP($A19,M_Sapi!$A$2:$B$501,2,0),"")) | F19: =IF(OR($A19="",$C19=""),"",$C19-$D19) | G19: =IF(OR($A19="",$B19=""),"",$B19-$E19) | H19: =IF(OR($G19="",$G19=0),"",$F19/$G19)
... D6001: =IF($A6001="","",IFERROR(VLOOKUP($A6001,M_Sapi!$A$2:$D$501,4,0),"")) | E6001: =IF($A6001="","",IFERROR(VLOOKUP($A6001,M_Sapi!$A$2:$B$501,2,0),"")) | F6001: =IF(OR($A6001="",$C6001=""),"",$C6001-$D6001) | G6001: =IF(OR($A6001="",$B6001=""),"",$B6001-$E6001) | H6001: =IF(OR($G6001="",$G6001=0),"",$F6001/$G6001)

Sheet Operasional
A1: Tgl | B1: Batch | C1: Jenis Biaya | D1: Jumlah | E1: Keterangan
A2: 45930 | B2: B001 | C2: Gaji Karyawan | D2: 4500000 | E2: Gaji 2 karyawan
A3: 45930 | B3: B001 | C3: Listrik | D3: 650000 | E3: Tagihan bulanan
A4: 45930 | B4: B001 | C4: BBM | D4: 500000 | E4: Solar chopper
A5: 45910 | B5: B001 | C5: Obat & Vitamin | D5: 800000 | E5: Vitamin B-complex

Sheet Penjualan
A1: Tgl Jual | B1: ID Sapi | C1: Bobot Jual (kg) | D1: Harga/kg | E1: Total Jual | F1: HPP/ekor | G1: Margin | H1: Margin %
E2: =IF($B2="","",$C2*$D2) | F2: =IF($B2="","",IFERROR(INDEX(HPP_Sapi!$I$2:$I$501,MATCH($B2,HPP_Sapi!$A$2:$A$501,0)),0)) | G2: =IF($B2="","",$E2-$F2) | H2: =IF(OR($B2="",$E2=0),"",$G2/$E2)
E3: =IF($B3="","",$C3*$D3) | F3: =IF($B3="","",IFERROR(INDEX(HPP_Sapi!$I$2:$I$501,MATCH($B3,HPP_Sapi!$A$2:$A$501,0)),0)) | G3: =IF($B3="","",$E3-$F3) | H3: =IF(OR($B3="",$E3=0),"",$G3/$E3)
E4: =IF($B4="","",$C4*$D4) | F4: =IF($B4="","",IFERROR(INDEX(HPP_Sapi!$I$2:$I$501,MATCH($B4,HPP_Sapi!$A$2:$A$501,0)),0)) | G4: =IF($B4="","",$E4-$F4) | H4: =IF(OR($B4="",$E4=0),"",$G4/$E4)
E5: =IF($B5="","",$C5*$D5) | F5: =IF($B5="","",IFERROR(INDEX(HPP_Sapi!$I$2:$I$501,MATCH($B5,HPP_Sapi!$A$2:$A$501,0)),0)) | G5: =IF($B5="","",$E5-$F5) | H5: =IF(OR($B5="",$E5=0),"",$G5/$E5)
E6: =IF($B6="","",$C6*$D6) | F6: =IF($B6="","",IFERROR(INDEX(HPP_Sapi!$I$2:$I$501,MATCH($B6,HPP_Sapi!$A$2:$A$501,0)),0)) | G6: =IF($B6="","",$E6-$F6) | H6: =IF(OR($B6="",$E6=0),"",$G6/$E6)
E7: =IF($B7="","",$C7*$D7) | F7: =IF($B7="","",IFERROR(INDEX(HPP_Sapi!$I$2:$I$501,MATCH($B7,HPP_Sapi!$A$2:$A$501,0)),0)) | G7: =IF($B7="","",$E7-$F7) | H7: =IF(OR($B7="",$E7=0),"",$G7/$E7)
E8: =IF($B8="","",$C8*$D8) | F8: =IF($B8="","",IFERROR(INDEX(HPP_Sapi!$I$2:$I$501,MATCH($B8,HPP_Sapi!$A$2:$A$501,0)),0)) | G8: =IF($B8="","",$E8-$F8) | H8: =IF(OR($B8="",$E8=0),"",$G8/$E8)
E9: =IF($B9="","",$C9*$D9) | F9: =IF($B9="","",IFERROR(INDEX(HPP_Sapi!$I$2:$I$501,MATCH($B9,HPP_Sapi!$A$2:$A$501,0)),0)) | G9: =IF($B9="","",$E9-$F9) | H9: =IF(OR($B9="",$E9=0),"",$G9/$E9)
E10: =IF($B10="","",$C10*$D10) | F10: =IF($B10="","",IFERROR(INDEX(HPP_Sapi!$I$2:$I$501,MATCH($B10,HPP_Sapi!$A$2:$A$501,0)),0)) | G10: =IF($B10="","",$E10-$F10) | H10: =IF(OR($B10="",$E10=0),"",$G10/$E10)
E11: =IF($B11="","",$C11*$D11) | F11: =IF($B11="","",IFERROR(INDEX(HPP_Sapi!$I$2:$I$501,MATCH($B11,HPP_Sapi!$A$2:$A$501,0)),0)) | G11: =IF($B11="","",$E11-$F11) | H11: =IF(OR($B11="",$E11=0),"",$G11/$E11)
E12: =IF($B12="","",$C12*$D12) | F12: =IF($B12="","",IFERROR(INDEX(HPP_Sapi!$I$2:$I$501,MATCH($B12,HPP_Sapi!$A$2:$A$501,0)),0)) | G12: =IF($B12="","",$E12-$F12) | H12: =IF(OR($B12="",$E12=0),"",$G12/$E12)
E13: =IF($B13="","",$C13*$D13) | F13: =IF($B13="","",IFERROR(INDEX(HPP_Sapi!$I$2:$I$501,MATCH($B13,HPP_Sapi!$A$2:$A$501,0)),0)) | G13: =IF($B13="","",$E13-$F13) | H13: =IF(OR($B13="",$E13=0),"",$G13/$E13)
... E1001: =IF($B1001="","",$C1001*$D1001) | F1001: =IF($B1001="","",IFERROR(INDEX(HPP_Sapi!$I$2:$I$501,MATCH($B1001,HPP_Sapi!$A$2:$A$501,0)),0)) | G1001: =IF($B1001="","",$E1001-$F1001) | H1001: =IF(OR($B1001="",$E1001=0),"",$G1001/$E1001)

Sheet Stok_Pakan
A1: Kode | B1: Nama Pakan | C1: Total Masuk (kg) | D1: Nilai Masuk | E1: Harga Rata2/kg | F1: Total Keluar (kg) | G1: Stok Akhir (kg) | H1: Nilai Stok Akhir | I1: Nilai Konsumsi
A2: =IF(M_Pakan!$A2="","",M_Pakan!$A2) | B2: =IF($A2="","",M_Pakan!$B2) | C2: =IF($A2="","",SUMIFS(Pakan_Masuk!$C$2:$C$3001,Pakan_Masuk!$B$2:$B$3001,$A2)) | D2: =IF($A2="","",SUMIFS(Pakan_Masuk!$D$2:$D$3001,Pakan_Masuk!$B$2:$B$3001,$A2)) | E2: =IF($A2="","",IFERROR($D2/$C2,0)) | F2: =IF($A2="","",SUMIFS(Pakan_Keluar!$D$2:$D$10001,Pakan_Keluar!$C$2:$C$10001,$A2)) | G2: =IF($A2="","",$C2-$F2) | H2: =IF($A2="","",$G2*$E2) | I2: =IF($A2="","",$F2*$E2)
A3: =IF(M_Pakan!$A3="","",M_Pakan!$A3) | B3: =IF($A3="","",M_Pakan!$B3) | C3: =IF($A3="","",SUMIFS(Pakan_Masuk!$C$2:$C$3001,Pakan_Masuk!$B$2:$B$3001,$A3)) | D3: =IF($A3="","",SUMIFS(Pakan_Masuk!$D$2:$D$3001,Pakan_Masuk!$B$2:$B$3001,$A3)) | E3: =IF($A3="","",IFERROR($D3/$C3,0)) | F3: =IF($A3="","",SUMIFS(Pakan_Keluar!$D$2:$D$10001,Pakan_Keluar!$C$2:$C$10001,$A3)) | G3: =IF($A3="","",$C3-$F3) | H3: =IF($A3="","",$G3*$E3) | I3: =IF($A3="","",$F3*$E3)
A4: =IF(M_Pakan!$A4="","",M_Pakan!$A4) | B4: =IF($A4="","",M_Pakan!$B4) | C4: =IF($A4="","",SUMIFS(Pakan_Masuk!$C$2:$C$3001,Pakan_Masuk!$B$2:$B$3001,$A4)) | D4: =IF($A4="","",SUMIFS(Pakan_Masuk!$D$2:$D$3001,Pakan_Masuk!$B$2:$B$3001,$A4)) | E4: =IF($A4="","",IFERROR($D4/$C4,0)) | F4: =IF($A4="","",SUMIFS(Pakan_Keluar!$D$2:$D$10001,Pakan_Keluar!$C$2:$C$10001,$A4)) | G4: =IF($A4="","",$C4-$F4) | H4: =IF($A4="","",$G4*$E4) | I4: =IF($A4="","",$F4*$E4)
A5: =IF(M_Pakan!$A5="","",M_Pakan!$A5) | B5: =IF($A5="","",M_Pakan!$B5) | C5: =IF($A5="","",SUMIFS(Pakan_Masuk!$C$2:$C$3001,Pakan_Masuk!$B$2:$B$3001,$A5)) | D5: =IF($A5="","",SUMIFS(Pakan_Masuk!$D$2:$D$3001,Pakan_Masuk!$B$2:$B$3001,$A5)) | E5: =IF($A5="","",IFERROR($D5/$C5,0)) | F5: =IF($A5="","",SUMIFS(Pakan_Keluar!$D$2:$D$10001,Pakan_Keluar!$C$2:$C$10001,$A5)) | G5: =IF($A5="","",$C5-$F5) | H5: =IF($A5="","",$G5*$E5) | I5: =IF($A5="","",$F5*$E5)
A6: =IF(M_Pakan!$A6="","",M_Pakan!$A6) | B6: =IF($A6="","",M_Pakan!$B6) | C6: =IF($A6="","",SUMIFS(Pakan_Masuk!$C$2:$C$3001,Pakan_Masuk!$B$2:$B$3001,$A6)) | D6: =IF($A6="","",SUMIFS(Pakan_Masuk!$D$2:$D$3001,Pakan_Masuk!$B$2:$B$3001,$A6)) | E6: =IF($A6="","",IFERROR($D6/$C6,0)) | F6: =IF($A6="","",SUMIFS(Pakan_Keluar!$D$2:$D$10001,Pakan_Keluar!$C$2:$C$10001,$A6)) | G6: =IF($A6="","",$C6-$F6) | H6: =IF($A6="","",$G6*$E6) | I6: =IF($A6="","",$F6*$E6)
A7: =IF(M_Pakan!$A7="","",M_Pakan!$A7) | B7: =IF($A7="","",M_Pakan!$B7) | C7: =IF($A7="","",SUMIFS(Pakan_Masuk!$C$2:$C$3001,Pakan_Masuk!$B$2:$B$3001,$A7)) | D7: =IF($A7="","",SUMIFS(Pakan_Masuk!$D$2:$D$3001,Pakan_Masuk!$B$2:$B$3001,$A7)) | E7: =IF($A7="","",IFERROR($D7/$C7,0)) | F7: =IF($A7="","",SUMIFS(Pakan_Keluar!$D$2:$D$10001,Pakan_Keluar!$C$2:$C$10001,$A7)) | G7: =IF($A7="","",$C7-$F7) | H7: =IF($A7="","",$G7*$E7) | I7: =IF($A7="","",$F7*$E7)
A8: =IF(M_Pakan!$A8="","",M_Pakan!$A8) | B8: =IF($A8="","",M_Pakan!$B8) | C8: =IF($A8="","",SUMIFS(Pakan_Masuk!$C$2:$C$3001,Pakan_Masuk!$B$2:$B$3001,$A8)) | D8: =IF($A8="","",SUMIFS(Pakan_Masuk!$D$2:$D$3001,Pakan_Masuk!$B$2:$B$3001,$A8)) | E8: =IF($A8="","",IFERROR($D8/$C8,0)) | F8: =IF($A8="","",SUMIFS(Pakan_Keluar!$D$2:$D$10001,Pakan_Keluar!$C$2:$C$10001,$A8)) | G8: =IF($A8="","",$C8-$F8) | H8: =IF($A8="","",$G8*$E8) | I8: =IF($A8="","",$F8*$E8)
A9: =IF(M_Pakan!$A9="","",M_Pakan!$A9) | B9: =IF($A9="","",M_Pakan!$B9) | C9: =IF($A9="","",SUMIFS(Pakan_Masuk!$C$2:$C$3001,Pakan_Masuk!$B$2:$B$3001,$A9)) | D9: =IF($A9="","",SUMIFS(Pakan_Masuk!$D$2:$D$3001,Pakan_Masuk!$B$2:$B$3001,$A9)) | E9: =IF($A9="","",IFERROR($D9/$C9,0)) | F9: =IF($A9="","",SUMIFS(Pakan_Keluar!$D$2:$D$10001,Pakan_Keluar!$C$2:$C$10001,$A9)) | G9: =IF($A9="","",$C9-$F9) | H9: =IF($A9="","",$G9*$E9) | I9: =IF($A9="","",$F9*$E9)
A10: =IF(M_Pakan!$A10="","",M_Pakan!$A10) | B10: =IF($A10="","",M_Pakan!$B10) | C10: =IF($A10="","",SUMIFS(Pakan_Masuk!$C$2:$C$3001,Pakan_Masuk!$B$2:$B$3001,$A10)) | D10: =IF($A10="","",SUMIFS(Pakan_Masuk!$D$2:$D$3001,Pakan_Masuk!$B$2:$B$3001,$A10)) | E10: =IF($A10="","",IFERROR($D10/$C10,0)) | F10: =IF($A10="","",SUMIFS(Pakan_Keluar!$D$2:$D$10001,Pakan_Keluar!$C$2:$C$10001,$A10)) | G10: =IF($A10="","",$C10-$F10) | H10: =IF($A10="","",$G10*$E10) | I10: =IF($A10="","",$F10*$E10)
A11: =IF(M_Pakan!$A11="","",M_Pakan!$A11) | B11: =IF($A11="","",M_Pakan!$B11) | C11: =IF($A11="","",SUMIFS(Pakan_Masuk!$C$2:$C$3001,Pakan_Masuk!$B$2:$B$3001,$A11)) | D11: =IF($A11="","",SUMIFS(Pakan_Masuk!$D$2:$D$3001,Pakan_Masuk!$B$2:$B$3001,$A11)) | E11: =IF($A11="","",IFERROR($D11/$C11,0)) | F11: =IF($A11="","",SUMIFS(Pakan_Keluar!$D$2:$D$10001,Pakan_Keluar!$C$2:$C$10001,$A11)) | G11: =IF($A11="","",$C11-$F11) | H11: =IF($A11="","",$G11*$E11) | I11: =IF($A11="","",$F11*$E11)
A12: =IF(M_Pakan!$A12="","",M_Pakan!$A12) | B12: =IF($A12="","",M_Pakan!$B12) | C12: =IF($A12="","",SUMIFS(Pakan_Masuk!$C$2:$C$3001,Pakan_Masuk!$B$2:$B$3001,$A12)) | D12: =IF($A12="","",SUMIFS(Pakan_Masuk!$D$2:$D$3001,Pakan_Masuk!$B$2:$B$3001,$A12)) | E12: =IF($A12="","",IFERROR($D12/$C12,0)) | F12: =IF($A12="","",SUMIFS(Pakan_Keluar!$D$2:$D$10001,Pakan_Keluar!$C$2:$C$10001,$A12)) | G12: =IF($A12="","",$C12-$F12) | H12: =IF($A12="","",$G12*$E12) | I12: =IF($A12="","",$F12*$E12)
A13: =IF(M_Pakan!$A13="","",M_Pakan!$A13) | B13: =IF($A13="","",M_Pakan!$B13) | C13: =IF($A13="","",SUMIFS(Pakan_Masuk!$C$2:$C$3001,Pakan_Masuk!$B$2:$B$3001,$A13)) | D13: =IF($A13="","",SUMIFS(Pakan_Masuk!$D$2:$D$3001,Pakan_Masuk!$B$2:$B$3001,$A13)) | E13: =IF($A13="","",IFERROR($D13/$C13,0)) | F13: =IF($A13="","",SUMIFS(Pakan_Keluar!$D$2:$D$10001,Pakan_Keluar!$C$2:$C$10001,$A13)) | G13: =IF($A13="","",$C13-$F13) | H13: =IF($A13="","",$G13*$E13) | I13: =IF($A13="","",$F13*$E13)
... A51: =IF(M_Pakan!$A51="","",M_Pakan!$A51) | B51: =IF($A51="","",M_Pakan!$B51) | C51: =IF($A51="","",SUMIFS(Pakan_Masuk!$C$2:$C$3001,Pakan_Masuk!$B$2:$B$3001,$A51)) | D51: =IF($A51="","",SUMIFS(Pakan_Masuk!$D$2:$D$3001,Pakan_Masuk!$B$2:$B$3001,$A51)) | E51: =IF($A51="","",IFERROR($D51/$C51,0)) | F51: =IF($A51="","",SUMIFS(Pakan_Keluar!$D$2:$D$10001,Pakan_Keluar!$C$2:$C$10001,$A51)) | G51: =IF($A51="","",$C51-$F51) | H51: =IF($A51="","",$G51*$E51) | I51: =IF($A51="","",$F51*$E51)

Sheet HPP_Sapi
A1: ID Sapi | B1: Batch | C1: Status | D1: Hari Pelihara | E1: Harga Beli | F1: Biaya Pakan (alokasi batch) | G1: Biaya Operasional (alokasi batch) | H1: Penyusutan (alokasi batch) | I1: HPP Total | J1: Bobot Terkini (kg) | K1: HPP per kg
A2: =IF(M_Sapi!$A2="","",M_Sapi!$A2) | B2: =IF($A2="","",M_Sapi!$F2) | C2: =IF($A2="","",M_Sapi!$J2) | D2: =IF($A2="","",M_Sapi!$L2) | E2: =IF($A2="","",M_Sapi!$E2) | F2: =IF($A2="","",IFERROR(INDEX(M_Batch!$K$2:$K$201,MATCH($B2,M_Batch!$A$2:$A$201,0))*$D2/INDEX(M_Batch!$J$2:$J$201,MATCH($B2,M_Batch!$A$2:$A$201,0)),0)) | G2: =IF($A2="","",IFERROR(INDEX(M_Batch!$L$2:$L$201,MATCH($B2,M_Batch!$A$2:$A$201,0))*$D2/INDEX(M_Batch!$J$2:$J$201,MATCH($B2,M_Batch!$A$2:$A$201,0)),0)) | H2: =IF($A2="","",IFERROR(INDEX(M_Batch!$M$2:$M$201,MATCH($B2,M_Batch!$A$2:$A$201,0))*$D2/INDEX(M_Batch!$J$2:$J$201,MATCH($B2,M_Batch!$A$2:$A$201,0)),0)) | I2: =IF($A2="","",$E2+$F2+$G2+$H2) | J2: =IF($A2="","",IF(COUNTIF(Penjualan!$B$2:$B$1001,$A2)>0,IFERROR(INDEX(Penjualan!$C$2:$C$1001,MATCH($A2,Penjualan!$B$2:$B$1001,0)),0),IFERROR(LOOKUP(2,1/(Timbang!$A$2:$A$6001=$A2),Timbang!$C$2:$C$6001),M_Sapi!$D2))) | K2: =IF($A2="","",IFERROR($I2/$J2,0))
A3: =IF(M_Sapi!$A3="","",M_Sapi!$A3) | B3: =IF($A3="","",M_Sapi!$F3) | C3: =IF($A3="","",M_Sapi!$J3) | D3: =IF($A3="","",M_Sapi!$L3) | E3: =IF($A3="","",M_Sapi!$E3) | F3: =IF($A3="","",IFERROR(INDEX(M_Batch!$K$2:$K$201,MATCH($B3,M_Batch!$A$2:$A$201,0))*$D3/INDEX(M_Batch!$J$2:$J$201,MATCH($B3,M_Batch!$A$2:$A$201,0)),0)) | G3: =IF($A3="","",IFERROR(INDEX(M_Batch!$L$2:$L$201,MATCH($B3,M_Batch!$A$2:$A$201,0))*$D3/INDEX(M_Batch!$J$2:$J$201,MATCH($B3,M_Batch!$A$2:$A$201,0)),0)) | H3: =IF($A3="","",IFERROR(INDEX(M_Batch!$M$2:$M$201,MATCH($B3,M_Batch!$A$2:$A$201,0))*$D3/INDEX(M_Batch!$J$2:$J$201,MATCH($B3,M_Batch!$A$2:$A$201,0)),0)) | I3: =IF($A3="","",$E3+$F3+$G3+$H3) | J3: =IF($A3="","",IF(COUNTIF(Penjualan!$B$2:$B$1001,$A3)>0,IFERROR(INDEX(Penjualan!$C$2:$C$1001,MATCH($A3,Penjualan!$B$2:$B$1001,0)),0),IFERROR(LOOKUP(2,1/(Timbang!$A$2:$A$6001=$A3),Timbang!$C$2:$C$6001),M_Sapi!$D3))) | K3: =IF($A3="","",IFERROR($I3/$J3,0))
A4: =IF(M_Sapi!$A4="","",M_Sapi!$A4) | B4: =IF($A4="","",M_Sapi!$F4) | C4: =IF($A4="","",M_Sapi!$J4) | D4: =IF($A4="","",M_Sapi!$L4) | E4: =IF($A4="","",M_Sapi!$E4) | F4: =IF($A4="","",IFERROR(INDEX(M_Batch!$K$2:$K$201,MATCH($B4,M_Batch!$A$2:$A$201,0))*$D4/INDEX(M_Batch!$J$2:$J$201,MATCH($B4,M_Batch!$A$2:$A$201,0)),0)) | G4: =IF($A4="","",IFERROR(INDEX(M_Batch!$L$2:$L$201,MATCH($B4,M_Batch!$A$2:$A$201,0))*$D4/INDEX(M_Batch!$J$2:$J$201,MATCH($B4,M_Batch!$A$2:$A$201,0)),0)) | H4: =IF($A4="","",IFERROR(INDEX(M_Batch!$M$2:$M$201,MATCH($B4,M_Batch!$A$2:$A$201,0))*$D4/INDEX(M_Batch!$J$2:$J$201,MATCH($B4,M_Batch!$A$2:$A$201,0)),0)) | I4: =IF($A4="","",$E4+$F4+$G4+$H4) | J4: =IF($A4="","",IF(COUNTIF(Penjualan!$B$2:$B$1001,$A4)>0,IFERROR(INDEX(Penjualan!$C$2:$C$1001,MATCH($A4,Penjualan!$B$2:$B$1001,0)),0),IFERROR(LOOKUP(2,1/(Timbang!$A$2:$A$6001=$A4),Timbang!$C$2:$C$6001),M_Sapi!$D4))) | K4: =IF($A4="","",IFERROR($I4/$J4,0))
A5: =IF(M_Sapi!$A5="","",M_Sapi!$A5) | B5: =IF($A5="","",M_Sapi!$F5) | C5: =IF($A5="","",M_Sapi!$J5) | D5: =IF($A5="","",M_Sapi!$L5) | E5: =IF($A5="","",M_Sapi!$E5) | F5: =IF($A5="","",IFERROR(INDEX(M_Batch!$K$2:$K$201,MATCH($B5,M_Batch!$A$2:$A$201,0))*$D5/INDEX(M_Batch!$J$2:$J$201,MATCH($B5,M_Batch!$A$2:$A$201,0)),0)) | G5: =IF($A5="","",IFERROR(INDEX(M_Batch!$L$2:$L$201,MATCH($B5,M_Batch!$A$2:$A$201,0))*$D5/INDEX(M_Batch!$J$2:$J$201,MATCH($B5,M_Batch!$A$2:$A$201,0)),0)) | H5: =IF($A5="","",IFERROR(INDEX(M_Batch!$M$2:$M$201,MATCH($B5,M_Batch!$A$2:$A$201,0))*$D5/INDEX(M_Batch!$J$2:$J$201,MATCH($B5,M_Batch!$A$2:$A$201,0)),0)) | I5: =IF($A5="","",$E5+$F5+$G5+$H5) | J5: =IF($A5="","",IF(COUNTIF(Penjualan!$B$2:$B$1001,$A5)>0,IFERROR(INDEX(Penjualan!$C$2:$C$1001,MATCH($A5,Penjualan!$B$2:$B$1001,0)),0),IFERROR(LOOKUP(2,1/(Timbang!$A$2:$A$6001=$A5),Timbang!$C$2:$C$6001),M_Sapi!$D5))) | K5: =IF($A5="","",IFERROR($I5/$J5,0))
A6: =IF(M_Sapi!$A6="","",M_Sapi!$A6) | B6: =IF($A6="","",M_Sapi!$F6) | C6: =IF($A6="","",M_Sapi!$J6) | D6: =IF($A6="","",M_Sapi!$L6) | E6: =IF($A6="","",M_Sapi!$E6) | F6: =IF($A6="","",IFERROR(INDEX(M_Batch!$K$2:$K$201,MATCH($B6,M_Batch!$A$2:$A$201,0))*$D6/INDEX(M_Batch!$J$2:$J$201,MATCH($B6,M_Batch!$A$2:$A$201,0)),0)) | G6: =IF($A6="","",IFERROR(INDEX(M_Batch!$L$2:$L$201,MATCH($B6,M_Batch!$A$2:$A$201,0))*$D6/INDEX(M_Batch!$J$2:$J$201,MATCH($B6,M_Batch!$A$2:$A$201,0)),0)) | H6: =IF($A6="","",IFERROR(INDEX(M_Batch!$M$2:$M$201,MATCH($B6,M_Batch!$A$2:$A$201,0))*$D6/INDEX(M_Batch!$J$2:$J$201,MATCH($B6,M_Batch!$A$2:$A$201,0)),0)) | I6: =IF($A6="","",$E6+$F6+$G6+$H6) | J6: =IF($A6="","",IF(COUNTIF(Penjualan!$B$2:$B$1001,$A6)>0,IFERROR(INDEX(Penjualan!$C$2:$C$1001,MATCH($A6,Penjualan!$B$2:$B$1001,0)),0),IFERROR(LOOKUP(2,1/(Timbang!$A$2:$A$6001=$A6),Timbang!$C$2:$C$6001),M_Sapi!$D6))) | K6: =IF($A6="","",IFERROR($I6/$J6,0))
A7: =IF(M_Sapi!$A7="","",M_Sapi!$A7) | B7: =IF($A7="","",M_Sapi!$F7) | C7: =IF($A7="","",M_Sapi!$J7) | D7: =IF($A7="","",M_Sapi!$L7) | E7: =IF($A7="","",M_Sapi!$E7) | F7: =IF($A7="","",IFERROR(INDEX(M_Batch!$K$2:$K$201,MATCH($B7,M_Batch!$A$2:$A$201,0))*$D7/INDEX(M_Batch!$J$2:$J$201,MATCH($B7,M_Batch!$A$2:$A$201,0)),0)) | G7: =IF($A7="","",IFERROR(INDEX(M_Batch!$L$2:$L$201,MATCH($B7,M_Batch!$A$2:$A$201,0))*$D7/INDEX(M_Batch!$J$2:$J$201,MATCH($B7,M_Batch!$A$2:$A$201,0)),0)) | H7: =IF($A7="","",IFERROR(INDEX(M_Batch!$M$2:$M$201,MATCH($B7,M_Batch!$A$2:$A$201,0))*$D7/INDEX(M_Batch!$J$2:$J$201,MATCH($B7,M_Batch!$A$2:$A$201,0)),0)) | I7: =IF($A7="","",$E7+$F7+$G7+$H7) | J7: =IF($A7="","",IF(COUNTIF(Penjualan!$B$2:$B$1001,$A7)>0,IFERROR(INDEX(Penjualan!$C$2:$C$1001,MATCH($A7,Penjualan!$B$2:$B$1001,0)),0),IFERROR(LOOKUP(2,1/(Timbang!$A$2:$A$6001=$A7),Timbang!$C$2:$C$6001),M_Sapi!$D7))) | K7: =IF($A7="","",IFERROR($I7/$J7,0))
A8: =IF(M_Sapi!$A8="","",M_Sapi!$A8) | B8: =IF($A8="","",M_Sapi!$F8) | C8: =IF($A8="","",M_Sapi!$J8) | D8: =IF($A8="","",M_Sapi!$L8) | E8: =IF($A8="","",M_Sapi!$E8) | F8: =IF($A8="","",IFERROR(INDEX(M_Batch!$K$2:$K$201,MATCH($B8,M_Batch!$A$2:$A$201,0))*$D8/INDEX(M_Batch!$J$2:$J$201,MATCH($B8,M_Batch!$A$2:$A$201,0)),0)) | G8: =IF($A8="","",IFERROR(INDEX(M_Batch!$L$2:$L$201,MATCH($B8,M_Batch!$A$2:$A$201,0))*$D8/INDEX(M_Batch!$J$2:$J$201,MATCH($B8,M_Batch!$A$2:$A$201,0)),0)) | H8: =IF($A8="","",IFERROR(INDEX(M_Batch!$M$2:$M$201,MATCH($B8,M_Batch!$A$2:$A$201,0))*$D8/INDEX(M_Batch!$J$2:$J$201,MATCH($B8,M_Batch!$A$2:$A$201,0)),0)) | I8: =IF($A8="","",$E8+$F8+$G8+$H8) | J8: =IF($A8="","",IF(COUNTIF(Penjualan!$B$2:$B$1001,$A8)>0,IFERROR(INDEX(Penjualan!$C$2:$C$1001,MATCH($A8,Penjualan!$B$2:$B$1001,0)),0),IFERROR(LOOKUP(2,1/(Timbang!$A$2:$A$6001=$A8),Timbang!$C$2:$C$6001),M_Sapi!$D8))) | K8: =IF($A8="","",IFERROR($I8/$J8,0))
A9: =IF(M_Sapi!$A9="","",M_Sapi!$A9) | B9: =IF($A9="","",M_Sapi!$F9) | C9: =IF($A9="","",M_Sapi!$J9) | D9: =IF($A9="","",M_Sapi!$L9) | E9: =IF($A9="","",M_Sapi!$E9) | F9: =IF($A9="","",IFERROR(INDEX(M_Batch!$K$2:$K$201,MATCH($B9,M_Batch!$A$2:$A$201,0))*$D9/INDEX(M_Batch!$J$2:$J$201,MATCH($B9,M_Batch!$A$2:$A$201,0)),0)) | G9: =IF($A9="","",IFERROR(INDEX(M_Batch!$L$2:$L$201,MATCH($B9,M_Batch!$A$2:$A$201,0))*$D9/INDEX(M_Batch!$J$2:$J$201,MATCH($B9,M_Batch!$A$2:$A$201,0)),0)) | H9: =IF($A9="","",IFERROR(INDEX(M_Batch!$M$2:$M$201,MATCH($B9,M_Batch!$A$2:$A$201,0))*$D9/INDEX(M_Batch!$J$2:$J$201,MATCH($B9,M_Batch!$A$2:$A$201,0)),0)) | I9: =IF($A9="","",$E9+$F9+$G9+$H9) | J9: =IF($A9="","",IF(COUNTIF(Penjualan!$B$2:$B$1001,$A9)>0,IFERROR(INDEX(Penjualan!$C$2:$C$1001,MATCH($A9,Penjualan!$B$2:$B$1001,0)),0),IFERROR(LOOKUP(2,1/(Timbang!$A$2:$A$6001=$A9),Timbang!$C$2:$C$6001),M_Sapi!$D9))) | K9: =IF($A9="","",IFERROR($I9/$J9,0))
A10: =IF(M_Sapi!$A10="","",M_Sapi!$A10) | B10: =IF($A10="","",M_Sapi!$F10) | C10: =IF($A10="","",M_Sapi!$J10) | D10: =IF($A10="","",M_Sapi!$L10) | E10: =IF($A10="","",M_Sapi!$E10) | F10: =IF($A10="","",IFERROR(INDEX(M_Batch!$K$2:$K$201,MATCH($B10,M_Batch!$A$2:$A$201,0))*$D10/INDEX(M_Batch!$J$2:$J$201,MATCH($B10,M_Batch!$A$2:$A$201,0)),0)) | G10: =IF($A10="","",IFERROR(INDEX(M_Batch!$L$2:$L$201,MATCH($B10,M_Batch!$A$2:$A$201,0))*$D10/INDEX(M_Batch!$J$2:$J$201,MATCH($B10,M_Batch!$A$2:$A$201,0)),0)) | H10: =IF($A10="","",IFERROR(INDEX(M_Batch!$M$2:$M$201,MATCH($B10,M_Batch!$A$2:$A$201,0))*$D10/INDEX(M_Batch!$J$2:$J$201,MATCH($B10,M_Batch!$A$2:$A$201,0)),0)) | I10: =IF($A10="","",$E10+$F10+$G10+$H10) | J10: =IF($A10="","",IF(COUNTIF(Penjualan!$B$2:$B$1001,$A10)>0,IFERROR(INDEX(Penjualan!$C$2:$C$1001,MATCH($A10,Penjualan!$B$2:$B$1001,0)),0),IFERROR(LOOKUP(2,1/(Timbang!$A$2:$A$6001=$A10),Timbang!$C$2:$C$6001),M_Sapi!$D10))) | K10: =IF($A10="","",IFERROR($I10/$J10,0))
A11: =IF(M_Sapi!$A11="","",M_Sapi!$A11) | B11: =IF($A11="","",M_Sapi!$F11) | C11: =IF($A11="","",M_Sapi!$J11) | D11: =IF($A11="","",M_Sapi!$L11) | E11: =IF($A11="","",M_Sapi!$E11) | F11: =IF($A11="","",IFERROR(INDEX(M_Batch!$K$2:$K$201,MATCH($B11,M_Batch!$A$2:$A$201,0))*$D11/INDEX(M_Batch!$J$2:$J$201,MATCH($B11,M_Batch!$A$2:$A$201,0)),0)) | G11: =IF($A11="","",IFERROR(INDEX(M_Batch!$L$2:$L$201,MATCH($B11,M_Batch!$A$2:$A$201,0))*$D11/INDEX(M_Batch!$J$2:$J$201,MATCH($B11,M_Batch!$A$2:$A$201,0)),0)) | H11: =IF($A11="","",IFERROR(INDEX(M_Batch!$M$2:$M$201,MATCH($B11,M_Batch!$A$2:$A$201,0))*$D11/INDEX(M_Batch!$J$2:$J$201,MATCH($B11,M_Batch!$A$2:$A$201,0)),0)) | I11: =IF($A11="","",$E11+$F11+$G11+$H11) | J11: =IF($A11="","",IF(COUNTIF(Penjualan!$B$2:$B$1001,$A11)>0,IFERROR(INDEX(Penjualan!$C$2:$C$1001,MATCH($A11,Penjualan!$B$2:$B$1001,0)),0),IFERROR(LOOKUP(2,1/(Timbang!$A$2:$A$6001=$A11),Timbang!$C$2:$C$6001),M_Sapi!$D11))) | K11: =IF($A11="","",IFERROR($I11/$J11,0))
A12: =IF(M_Sapi!$A12="","",M_Sapi!$A12) | B12: =IF($A12="","",M_Sapi!$F12) | C12: =IF($A12="","",M_Sapi!$J12) | D12: =IF($A12="","",M_Sapi!$L12) | E12: =IF($A12="","",M_Sapi!$E12) | F12: =IF($A12="","",IFERROR(INDEX(M_Batch!$K$2:$K$201,MATCH($B12,M_Batch!$A$2:$A$201,0))*$D12/INDEX(M_Batch!$J$2:$J$201,MATCH($B12,M_Batch!$A$2:$A$201,0)),0)) | G12: =IF($A12="","",IFERROR(INDEX(M_Batch!$L$2:$L$201,MATCH($B12,M_Batch!$A$2:$A$201,0))*$D12/INDEX(M_Batch!$J$2:$J$201,MATCH($B12,M_Batch!$A$2:$A$201,0)),0)) | H12: =IF($A12="","",IFERROR(INDEX(M_Batch!$M$2:$M$201,MATCH($B12,M_Batch!$A$2:$A$201,0))*$D12/INDEX(M_Batch!$J$2:$J$201,MATCH($B12,M_Batch!$A$2:$A$201,0)),0)) | I12: =IF($A12="","",$E12+$F12+$G12+$H12) | J12: =IF($A12="","",IF(COUNTIF(Penjualan!$B$2:$B$1001,$A12)>0,IFERROR(INDEX(Penjualan!$C$2:$C$1001,MATCH($A12,Penjualan!$B$2:$B$1001,0)),0),IFERROR(LOOKUP(2,1/(Timbang!$A$2:$A$6001=$A12),Timbang!$C$2:$C$6001),M_Sapi!$D12))) | K12: =IF($A12="","",IFERROR($I12/$J12,0))
A13: =IF(M_Sapi!$A13="","",M_Sapi!$A13) | B13: =IF($A13="","",M_Sapi!$F13) | C13: =IF($A13="","",M_Sapi!$J13) | D13: =IF($A13="","",M_Sapi!$L13) | E13: =IF($A13="","",M_Sapi!$E13) | F13: =IF($A13="","",IFERROR(INDEX(M_Batch!$K$2:$K$201,MATCH($B13,M_Batch!$A$2:$A$201,0))*$D13/INDEX(M_Batch!$J$2:$J$201,MATCH($B13,M_Batch!$A$2:$A$201,0)),0)) | G13: =IF($A13="","",IFERROR(INDEX(M_Batch!$L$2:$L$201,MATCH($B13,M_Batch!$A$2:$A$201,0))*$D13/INDEX(M_Batch!$J$2:$J$201,MATCH($B13,M_Batch!$A$2:$A$201,0)),0)) | H13: =IF($A13="","",IFERROR(INDEX(M_Batch!$M$2:$M$201,MATCH($B13,M_Batch!$A$2:$A$201,0))*$D13/INDEX(M_Batch!$J$2:$J$201,MATCH($B13,M_Batch!$A$2:$A$201,0)),0)) | I13: =IF($A13="","",$E13+$F13+$G13+$H13) | J13: =IF($A13="","",IF(COUNTIF(Penjualan!$B$2:$B$1001,$A13)>0,IFERROR(INDEX(Penjualan!$C$2:$C$1001,MATCH($A13,Penjualan!$B$2:$B$1001,0)),0),IFERROR(LOOKUP(2,1/(Timbang!$A$2:$A$6001=$A13),Timbang!$C$2:$C$6001),M_Sapi!$D13))) | K13: =IF($A13="","",IFERROR($I13/$J13,0))
... A501: =IF(M_Sapi!$A501="","",M_Sapi!$A501) | B501: =IF($A501="","",M_Sapi!$F501) | C501: =IF($A501="","",M_Sapi!$J501) | D501: =IF($A501="","",M_Sapi!$L501) | E501: =IF($A501="","",M_Sapi!$E501) | F501: =IF($A501="","",IFERROR(INDEX(M_Batch!$K$2:$K$201,MATCH($B501,M_Batch!$A$2:$A$201,0))*$D501/INDEX(M_Batch!$J$2:$J$201,MATCH($B501,M_Batch!$A$2:$A$201,0)),0)) | G501: =IF($A501="","",IFERROR(INDEX(M_Batch!$L$2:$L$201,MATCH($B501,M_Batch!$A$2:$A$201,0))*$D501/INDEX(M_Batch!$J$2:$J$201,MATCH($B501,M_Batch!$A$2:$A$201,0)),0)) | H501: =IF($A501="","",IFERROR(INDEX(M_Batch!$M$2:$M$201,MATCH($B501,M_Batch!$A$2:$A$201,0))*$D501/INDEX(M_Batch!$J$2:$J$201,MATCH($B501,M_Batch!$A$2:$A$201,0)),0)) | I501: =IF($A501="","",$E501+$F501+$G501+$H501) | J501: =IF($A501="","",IF(COUNTIF(Penjualan!$B$2:$B$1001,$A501)>0,IFERROR(INDEX(Penjualan!$C$2:$C$1001,MATCH($A501,Penjualan!$B$2:$B$1001,0)),0),IFERROR(LOOKUP(2,1/(Timbang!$A$2:$A$6001=$A501),Timbang!$C$2:$C$6001),M_Sapi!$D501))) | K501: =IF($A501="","",IFERROR($I501/$J501,0))

Sheet Lap_Keuangan
B1: LAPORAN KEUANGAN — Usaha Penggemukan Sapi
B3: A. LABA RUGI
B4: Pendapatan Penjualan Sapi | D4: =SUM(Penjualan!$E$2:$E$1001)
B5: (-) HPP Sapi Terjual | D5: =SUMIFS(HPP_Sapi!$I$2:$I$501,HPP_Sapi!$C$2:$C$501,"Terjual")
B6: Laba Kotor | D6: =D4-D5
B7: (-) Kerugian Sapi Mati/Afkir | D7: =SUMIFS(HPP_Sapi!$I$2:$I$501,HPP_Sapi!$C$2:$C$501,"Mati")
B8: LABA BERSIH | D8: =D6-D7
B10: B. ARUS KAS (Metode Langsung)
B11: Kas Masuk — Modal Disetor | D11: =MENU!$B$5
B12: Kas Masuk — Penjualan Sapi | D12: =D4
B13: Total Kas Masuk | D13: =D11+D12
B14: Kas Keluar — Beli Sapi Bakalan | D14: =SUM(M_Sapi!$E$2:$E$501)
B15: Kas Keluar — Beli Pakan | D15: =SUM(Pakan_Masuk!$D$2:$D$3001)
B16: Kas Keluar — Biaya Operasional | D16: =SUM(Operasional!$D$2:$D$3001)
B17: Kas Keluar — Beli Aset Tetap | D17: =SUM(M_AsetTetap!$C$2:$C$51)
B18: Total Kas Keluar | D18: =D14+D15+D16+D17
B19: SALDO KAS AKHIR | D19: =D13-D18
B21: C. NERACA
B22: ASET
B23: Kas | D23: =D19
B24: Persediaan Sapi (Aktif) | D24: =SUMIFS(HPP_Sapi!$I$2:$I$501,HPP_Sapi!$C$2:$C$501,"Aktif")
B25: Persediaan Pakan | D25: =SUM(Stok_Pakan!$H$2:$H$51)
B26: Aset Tetap (Nilai Buku) | D26: =SUM(M_AsetTetap!$C$2:$C$51)-SUM(M_Batch!$M$2:$M$201)
B27: TOTAL ASET | D27: =D23+D24+D25+D26
B29: PASIVA & MODAL
B30: Modal Disetor | D30: =MENU!$B$5
B31: Laba Ditahan (akumulasi laba bersih) | D31: =D8
B32: TOTAL PASIVA & MODAL | D32: =D30+D31
B34: Cek Keseimbangan (harus = 0) | D34: =D27-D32
B36: Catatan: Biaya pakan, operasional & penyusutan dikelompokkan per BATCH lalu menempel ke sapi (metode HPP akurat). Setelah batch ditutup (Tgl Selesai diisi), biaya & HPP batch tsb TERKUNCI sehingga margin penjualan historis tidak berubah walau ada batch/biaya periode baru. Penyusutan diakui sepanjang batch berjalan = (penyusutan/bln semua aset) x lama batch.

Sheet Analisis
A1: ID Sapi | B1: Batch | C1: Status | D1: Bobot Awal | E1: Bobot Akhir | F1: Pertambahan | G1: Hari | H1: ADG (kg/hr) | I1: HPP Total | J1: Harga Jual | K1: Margin | L1: Margin % | N1: Batch | O1: Status | P1: Jumlah Sapi | Q1: Total Gain (kg) | R1: Total Biaya Pakan | S1: FCG (Rp/kg gain) | T1: ADG Rata2
A2: =IF(M_Sapi!$A2="","",M_Sapi!$A2) | B2: =IF($A2="","",M_Sapi!$F2) | C2: =IF($A2="","",M_Sapi!$J2) | D2: =IF($A2="","",M_Sapi!$D2) | E2: =IF($A2="","",HPP_Sapi!$J2) | F2: =IF($A2="","",$E2-$D2) | G2: =IF($A2="","",M_Sapi!$L2) | H2: =IF(OR($A2="",$G2=0),"",$F2/$G2) | I2: =IF($A2="","",HPP_Sapi!$I2) | J2: =IF($A2="","",IFERROR(INDEX(Penjualan!$E$2:$E$1001,MATCH($A2,Penjualan!$B$2:$B$1001,0)),0)) | K2: =IF($A2="","",IF($J2=0,0,$J2-$I2)) | L2: =IF(OR($A2="",$J2=0),"",$K2/$J2) | N2: =IF(M_Batch!$A2="","",M_Batch!$A2) | O2: =IF($N2="","",M_Batch!$F2) | P2: =IF($N2="","",M_Batch!$I2) | Q2: =IF($N2="","",SUMIFS($F$2:$F$501,$B$2:$B$501,$N2)) | R2: =IF($N2="","",M_Batch!$K2) | S2: =IF($N2="","",IFERROR($R2/$Q2,0)) | T2: =IF($N2="","",IFERROR(AVERAGEIFS($H$2:$H$501,$B$2:$B$501,$N2),0))
A3: =IF(M_Sapi!$A3="","",M_Sapi!$A3) | B3: =IF($A3="","",M_Sapi!$F3) | C3: =IF($A3="","",M_Sapi!$J3) | D3: =IF($A3="","",M_Sapi!$D3) | E3: =IF($A3="","",HPP_Sapi!$J3) | F3: =IF($A3="","",$E3-$D3) | G3: =IF($A3="","",M_Sapi!$L3) | H3: =IF(OR($A3="",$G3=0),"",$F3/$G3) | I3: =IF($A3="","",HPP_Sapi!$I3) | J3: =IF($A3="","",IFERROR(INDEX(Penjualan!$E$2:$E$1001,MATCH($A3,Penjualan!$B$2:$B$1001,0)),0)) | K3: =IF($A3="","",IF($J3=0,0,$J3-$I3)) | L3: =IF(OR($A3="",$J3=0),"",$K3/$J3) | N3: =IF(M_Batch!$A3="","",M_Batch!$A3) | O3: =IF($N3="","",M_Batch!$F3) | P3: =IF($N3="","",M_Batch!$I3) | Q3: =IF($N3="","",SUMIFS($F$2:$F$501,$B$2:$B$501,$N3)) | R3: =IF($N3="","",M_Batch!$K3) | S3: =IF($N3="","",IFERROR($R3/$Q3,0)) | T3: =IF($N3="","",IFERROR(AVERAGEIFS($H$2:$H$501,$B$2:$B$501,$N3),0))
A4: =IF(M_Sapi!$A4="","",M_Sapi!$A4) | B4: =IF($A4="","",M_Sapi!$F4) | C4: =IF($A4="","",M_Sapi!$J4) | D4: =IF($A4="","",M_Sapi!$D4) | E4: =IF($A4="","",HPP_Sapi!$J4) | F4: =IF($A4="","",$E4-$D4) | G4: =IF($A4="","",M_Sapi!$L4) | H4: =IF(OR($A4="",$G4=0),"",$F4/$G4) | I4: =IF($A4="","",HPP_Sapi!$I4) | J4: =IF($A4="","",IFERROR(INDEX(Penjualan!$E$2:$E$1001,MATCH($A4,Penjualan!$B$2:$B$1001,0)),0)) | K4: =IF($A4="","",IF($J4=0,0,$J4-$I4)) | L4: =IF(OR($A4="",$J4=0),"",$K4/$J4) | N4: =IF(M_Batch!$A4="","",M_Batch!$A4) | O4: =IF($N4="","",M_Batch!$F4) | P4: =IF($N4="","",M_Batch!$I4) | Q4: =IF($N4="","",SUMIFS($F$2:$F$501,$B$2:$B$501,$N4)) | R4: =IF($N4="","",M_Batch!$K4) | S4: =IF($N4="","",IFERROR($R4/$Q4,0)) | T4: =IF($N4="","",IFERROR(AVERAGEIFS($H$2:$H$501,$B$2:$B$501,$N4),0))
A5: =IF(M_Sapi!$A5="","",M_Sapi!$A5) | B5: =IF($A5="","",M_Sapi!$F5) | C5: =IF($A5="","",M_Sapi!$J5) | D5: =IF($A5="","",M_Sapi!$D5) | E5: =IF($A5="","",HPP_Sapi!$J5) | F5: =IF($A5="","",$E5-$D5) | G5: =IF($A5="","",M_Sapi!$L5) | H5: =IF(OR($A5="",$G5=0),"",$F5/$G5) | I5: =IF($A5="","",HPP_Sapi!$I5) | J5: =IF($A5="","",IFERROR(INDEX(Penjualan!$E$2:$E$1001,MATCH($A5,Penjualan!$B$2:$B$1001,0)),0)) | K5: =IF($A5="","",IF($J5=0,0,$J5-$I5)) | L5: =IF(OR($A5="",$J5=0),"",$K5/$J5) | N5: =IF(M_Batch!$A5="","",M_Batch!$A5) | O5: =IF($N5="","",M_Batch!$F5) | P5: =IF($N5="","",M_Batch!$I5) | Q5: =IF($N5="","",SUMIFS($F$2:$F$501,$B$2:$B$501,$N5)) | R5: =IF($N5="","",M_Batch!$K5) | S5: =IF($N5="","",IFERROR($R5/$Q5,0)) | T5: =IF($N5="","",IFERROR(AVERAGEIFS($H$2:$H$501,$B$2:$B$501,$N5),0))
A6: =IF(M_Sapi!$A6="","",M_Sapi!$A6) | B6: =IF($A6="","",M_Sapi!$F6) | C6: =IF($A6="","",M_Sapi!$J6) | D6: =IF($A6="","",M_Sapi!$D6) | E6: =IF($A6="","",HPP_Sapi!$J6) | F6: =IF($A6="","",$E6-$D6) | G6: =IF($A6="","",M_Sapi!$L6) | H6: =IF(OR($A6="",$G6=0),"",$F6/$G6) | I6: =IF($A6="","",HPP_Sapi!$I6) | J6: =IF($A6="","",IFERROR(INDEX(Penjualan!$E$2:$E$1001,MATCH($A6,Penjualan!$B$2:$B$1001,0)),0)) | K6: =IF($A6="","",IF($J6=0,0,$J6-$I6)) | L6: =IF(OR($A6="",$J6=0),"",$K6/$J6) | N6: =IF(M_Batch!$A6="","",M_Batch!$A6) | O6: =IF($N6="","",M_Batch!$F6) | P6: =IF($N6="","",M_Batch!$I6) | Q6: =IF($N6="","",SUMIFS($F$2:$F$501,$B$2:$B$501,$N6)) | R6: =IF($N6="","",M_Batch!$K6) | S6: =IF($N6="","",IFERROR($R6/$Q6,0)) | T6: =IF($N6="","",IFERROR(AVERAGEIFS($H$2:$H$501,$B$2:$B$501,$N6),0))
A7: =IF(M_Sapi!$A7="","",M_Sapi!$A7) | B7: =IF($A7="","",M_Sapi!$F7) | C7: =IF($A7="","",M_Sapi!$J7) | D7: =IF($A7="","",M_Sapi!$D7) | E7: =IF($A7="","",HPP_Sapi!$J7) | F7: =IF($A7="","",$E7-$D7) | G7: =IF($A7="","",M_Sapi!$L7) | H7: =IF(OR($A7="",$G7=0),"",$F7/$G7) | I7: =IF($A7="","",HPP_Sapi!$I7) | J7: =IF($A7="","",IFERROR(INDEX(Penjualan!$E$2:$E$1001,MATCH($A7,Penjualan!$B$2:$B$1001,0)),0)) | K7: =IF($A7="","",IF($J7=0,0,$J7-$I7)) | L7: =IF(OR($A7="",$J7=0),"",$K7/$J7) | N7: =IF(M_Batch!$A7="","",M_Batch!$A7) | O7: =IF($N7="","",M_Batch!$F7) | P7: =IF($N7="","",M_Batch!$I7) | Q7: =IF($N7="","",SUMIFS($F$2:$F$501,$B$2:$B$501,$N7)) | R7: =IF($N7="","",M_Batch!$K7) | S7: =IF($N7="","",IFERROR($R7/$Q7,0)) | T7: =IF($N7="","",IFERROR(AVERAGEIFS($H$2:$H$501,$B$2:$B$501,$N7),0))
